INFO 2025-10-30 12:57:55,687 autoreload 15854 4564125184 Watching for file changes with StatReloader
WARNING 2025-10-30 12:57:58,995 log 15854 123145586184192 Not Found: /ws/market/
WARNING 2025-10-30 12:57:58,996 log 15854 123145602973696 Not Found: /ws/market/
WARNING 2025-10-30 12:58:02,063 log 15854 123145619763200 Not Found: /ws/market/
WARNING 2025-10-30 12:58:03,069 log 15854 123145620836352 Not Found: /ws/market/
INFO 2025-10-30 12:58:03,070 crypto_api_service 15854 123145586184192 CoinGecko API success: fetched 5 coins
INFO 2025-10-30 12:58:03,081 crypto_api_service 15854 123145586184192 Successfully fetched data from _fetch_from_coingecko
INFO 2025-10-30 12:58:03,131 crypto_api_service 15854 123145586184192 Updated 5 cryptocurrencies
INFO 2025-10-30 12:58:03,135 user_views 15854 123145586184192 Cryptocurrency data updated successfully
INFO 2025-10-30 12:58:03,721 crypto_api_service 15854 123145586184192 CoinGecko API success: fetched 5 coins
INFO 2025-10-30 12:58:03,726 crypto_api_service 15854 123145586184192 Successfully fetched data from _fetch_from_coingecko
INFO 2025-10-30 12:58:03,744 crypto_api_service 15854 123145586184192 Updated 5 cryptocurrencies
WARNING 2025-10-30 12:58:07,043 log 15854 123145687994368 Not Found: /ws/market/
INFO 2025-10-30 12:58:14,109 cli 15885 4689876480 Starting server at tcp:port=8000:interface=127.0.0.1
INFO 2025-10-30 12:58:14,109 server 15885 4689876480 HTTP/2 support enabled
INFO 2025-10-30 12:58:14,110 server 15885 4689876480 Configuring endpoint tcp:port=8000:interface=127.0.0.1
INFO 2025-10-30 12:58:14,183 server 15885 4689876480 Listening on TCP address 127.0.0.1:8000
INFO 2025-10-30 12:58:15,203 consumers 15885 4689876480 Market WebSocket connected: specific..inmemory!rXtgUitoQCtn
WARNING 2025-10-30 12:58:17,266 log 15885 123145633116160 Not Found: /static/assets/css.css
WARNING 2025-10-30 12:58:17,367 log 15885 123145633116160 Not Found: /static/assets/js/wow.js
WARNING 2025-10-30 12:58:17,369 log 15885 123145633116160 Not Found: /static/assets/js/wow.min.js
INFO 2025-10-30 12:58:17,383 crypto_api_service 15885 123145564884992 CoinGecko: Fetched 284 data points for BTC
WARNING 2025-10-30 12:58:17,444 log 15885 123145633116160 Not Found: /World FX CO LTD_files/googlelogo_color_42x16dp.png
WARNING 2025-10-30 12:58:17,584 log 15885 123145633116160 Not Found: /gtranslate.net/flags/24.png
WARNING 2025-10-30 12:58:18,476 log 15885 123145616326656 Not Found: /static/assets/css/fonts/UniSansHeavyCAPS.woff2
WARNING 2025-10-30 12:58:18,477 log 15885 123145633116160 Not Found: /static/assets/css/fonts/UniSansThinCAPS.woff2
WARNING 2025-10-30 12:58:18,646 log 15885 123145633116160 Not Found: /static/assets/css/fonts/UniSansHeavyCAPS.woff
WARNING 2025-10-30 12:58:18,920 log 15885 123145633116160 Not Found: /static/assets/css/fonts/UniSansThinCAPS.woff
WARNING 2025-10-30 12:58:19,201 log 15885 123145633116160 Not Found: /static/assets/css/fonts/UniSansHeavyCAPS.ttf
WARNING 2025-10-30 12:58:19,271 log 15885 123145633116160 Not Found: /static/assets/css/fonts/UniSansThinCAPS.ttf
WARNING 2025-10-30 12:58:26,489 log 15885 123145616326656 Not Found: /gtranslate.net/flags/24a.png
WARNING 2025-10-30 12:58:29,076 log 15885 123145633116160 Not Found: /static/assets/js/wow.js
WARNING 2025-10-30 12:58:29,080 log 15885 123145666695168 Not Found: /static/assets/css.css
WARNING 2025-10-30 12:58:29,088 log 15885 123145666695168 Not Found: /static/assets/js/wow.min.js
WARNING 2025-10-30 12:58:29,535 log 15885 123145666695168 Not Found: /static/assets/js/cubeb86a.js
WARNING 2025-10-30 12:58:29,538 log 15885 123145616326656 Not Found: /static/assets/js/1fonjd21.js
WARNING 2025-10-30 12:58:29,556 log 15885 123145633116160 Not Found: /login/gtranslate.net/flags/24.png
WARNING 2025-10-30 12:58:29,557 log 15885 123145616326656 Not Found: /login/er.lrticker.html
WARNING 2025-10-30 12:58:29,558 log 15885 123145616326656 Not Found: /login/World FX CO LTD_files/googlelogo_color_42x16dp.png
WARNING 2025-10-30 12:58:29,811 log 15885 123145666695168 Not Found: /static/assets/fonts/Quicksand/Quicksand-Regular.ttf
WARNING 2025-10-30 12:58:29,812 log 15885 123145616326656 Not Found: /static/assets/fonts/fontawesome-webfont3e6e.woff2
WARNING 2025-10-30 12:58:29,814 log 15885 123145633116160 Not Found: /static/assets/fonts/Quicksand/Quicksand-Bold.ttf
WARNING 2025-10-30 12:58:29,892 log 15885 123145633116160 Not Found: /static/assets/fonts/fontawesome-webfont3e6e.woff
WARNING 2025-10-30 12:58:29,957 log 15885 123145633116160 Not Found: /static/assets/fonts/fontawesome-webfont3e6e.ttf
INFO 2025-10-30 12:58:40,166 crypto_api_service 15885 123145582211072 CoinGecko API success: fetched 5 coins
INFO 2025-10-30 12:58:40,170 crypto_api_service 15885 123145582211072 Successfully fetched data from _fetch_from_coingecko
INFO 2025-10-30 12:58:40,187 crypto_api_service 15885 123145582211072 Updated 5 cryptocurrencies
INFO 2025-10-30 12:58:43,398 consumers 15885 4689876480 Market WebSocket connected: specific..inmemory!epshoigNWlKW
INFO 2025-10-30 12:58:46,132 crypto_api_service 15885 123145564884992 CoinGecko: Fetched 283 data points for BTC
INFO 2025-10-30 12:59:28,587 api_views 15885 123145582211072 Buy API called with data: {'transaction_type': 'BUY', 'cryptocurrency': 'USDT', 'quantity': 4, 'price_per_unit': 1, 'total_amount': 4.004, 'currency': 'USD'}
INFO 2025-10-30 12:59:28,593 api_views 15885 123145582211072 Balance updated for aghason.emmanuel@gmail.com: -4.00 USD, +4.00000000 USDT
INFO 2025-10-30 12:59:28,607 email_service 15885 123145582211072 Attempting to send verification email to aghason.emmanuel@gmail.com
INFO 2025-10-30 12:59:28,607 email_service 15885 123145582211072 Using SMTP: localhost:25
INFO 2025-10-30 12:59:28,607 email_service 15885 123145582211072 From: aghason.emmanuel@gmail.com
INFO 2025-10-30 12:59:28,755 email_service 15885 123145582211072 Verification code email sent successfully to aghason.emmanuel@gmail.com
INFO 2025-10-30 12:59:28,755 api_views 15885 123145582211072 Verification code sent to aghason.emmanuel@gmail.com
INFO 2025-10-30 13:00:06,642 consumers 15885 4689876480 Market WebSocket disconnected: specific..inmemory!epshoigNWlKW
INFO 2025-10-30 13:00:06,860 consumers 15885 4689876480 Market WebSocket connected: specific..inmemory!UpiusOAAmnrs
INFO 2025-10-30 13:00:09,612 crypto_api_service 15885 123145564884992 CoinGecko: Fetched 283 data points for BTC
INFO 2025-10-30 13:00:27,420 crypto_api_service 15885 123145582211072 CoinGecko API success: fetched 5 coins
INFO 2025-10-30 13:00:27,424 crypto_api_service 15885 123145582211072 Successfully fetched data from _fetch_from_coingecko
INFO 2025-10-30 13:00:27,441 crypto_api_service 15885 123145582211072 Updated 5 cryptocurrencies
INFO 2025-10-30 13:00:27,665 consumers 15885 4689876480 Market WebSocket disconnected: specific..inmemory!UpiusOAAmnrs
INFO 2025-10-30 13:01:15,350 server 15885 4689876480 Killed 1 pending application instances
INFO 2025-10-30 13:02:18,168 cli 16481 4477990400 Starting server at tcp:port=8000:interface=127.0.0.1
INFO 2025-10-30 13:02:18,169 server 16481 4477990400 HTTP/2 support enabled
INFO 2025-10-30 13:02:18,169 server 16481 4477990400 Configuring endpoint tcp:port=8000:interface=127.0.0.1
INFO 2025-10-30 13:02:18,172 server 16481 4477990400 Listening on TCP address 127.0.0.1:8000
INFO 2025-10-30 13:02:20,058 crypto_api_service 16481 123145352216576 CoinGecko API success: fetched 5 coins
INFO 2025-10-30 13:02:20,061 crypto_api_service 16481 123145352216576 Successfully fetched data from _fetch_from_coingecko
INFO 2025-10-30 13:02:20,198 crypto_api_service 16481 123145352216576 Updated 5 cryptocurrencies
INFO 2025-10-30 13:02:22,884 consumers 16481 4477990400 Market WebSocket connected: specific..inmemory!kyfsusMDihty
INFO 2025-10-30 13:02:24,848 crypto_api_service 16481 123145352216576 CoinGecko: Fetched 282 data points for BTC
INFO 2025-10-30 13:02:44,296 consumers 16481 4477990400 Market WebSocket connected: specific..inmemory!PFNlIgyOtksj
INFO 2025-10-30 13:02:46,256 crypto_api_service 16481 123145352216576 CoinGecko: Fetched 282 data points for BTC
INFO 2025-10-30 13:03:07,095 api_views 16481 123145369542656 Buy API called with data: {'transaction_type': 'BUY', 'cryptocurrency': 'LTC', 'quantity': 1, 'price_per_unit': 95.44, 'total_amount': 95.53544, 'currency': 'USD'}
INFO 2025-10-30 13:03:07,106 api_views 16481 123145369542656 Balance updated for aghason.emmanuel@gmail.com: -95.54 USD, +1.00000000 LTC
INFO 2025-10-30 13:03:07,120 email_service 16481 123145369542656 Attempting to send verification email to aghason.emmanuel@gmail.com
INFO 2025-10-30 13:03:07,121 email_service 16481 123145369542656 Using SMTP: localhost:25
INFO 2025-10-30 13:03:07,121 email_service 16481 123145369542656 From: aghason.emmanuel@gmail.com
INFO 2025-10-30 13:03:07,268 email_service 16481 123145369542656 Verification code email sent successfully to aghason.emmanuel@gmail.com
INFO 2025-10-30 13:03:07,268 api_views 16481 123145369542656 Verification code sent to aghason.emmanuel@gmail.com
INFO 2025-10-30 13:03:32,604 consumers 16481 4477990400 Market WebSocket disconnected: specific..inmemory!PFNlIgyOtksj
INFO 2025-10-30 13:03:32,767 consumers 16481 4477990400 Market WebSocket connected: specific..inmemory!pmIKWTRTwZNb
INFO 2025-10-30 13:03:33,665 crypto_api_service 16481 123145352216576 CoinGecko: Fetched 283 data points for BTC
INFO 2025-10-30 13:03:44,212 crypto_api_service 16481 123145369542656 CoinGecko API success: fetched 5 coins
INFO 2025-10-30 13:03:44,216 crypto_api_service 16481 123145369542656 Successfully fetched data from _fetch_from_coingecko
INFO 2025-10-30 13:03:44,228 crypto_api_service 16481 123145369542656 Updated 5 cryptocurrencies
INFO 2025-10-30 13:03:44,354 consumers 16481 4477990400 Market WebSocket disconnected: specific..inmemory!pmIKWTRTwZNb
INFO 2025-10-30 13:04:01,550 consumers 16481 4477990400 Market WebSocket connected: specific..inmemory!SndWHnIkWrgA
INFO 2025-10-30 13:04:03,274 crypto_api_service 16481 123145352216576 CoinGecko: Fetched 283 data points for BTC
INFO 2025-10-30 13:04:09,381 crypto_api_service 16481 123145369542656 CoinGecko API success: fetched 5 coins
INFO 2025-10-30 13:04:09,384 crypto_api_service 16481 123145369542656 Successfully fetched data from _fetch_from_coingecko
INFO 2025-10-30 13:04:09,398 crypto_api_service 16481 123145369542656 Updated 5 cryptocurrencies
INFO 2025-10-30 13:04:30,243 api_views 16481 123145369542656 Buy API called with data: {'transaction_type': 'BUY', 'cryptocurrency': 'USDT', 'quantity': 10, 'price_per_unit': 1, 'total_amount': 10.01, 'currency': 'USD'}
INFO 2025-10-30 13:04:30,253 api_views 16481 123145369542656 Balance updated for aghason.emmanuel@gmail.com: -10.01 USD, +10.00000000 USDT
INFO 2025-10-30 13:04:30,261 email_service 16481 123145369542656 Attempting to send verification email to aghason.emmanuel@gmail.com
INFO 2025-10-30 13:04:30,261 email_service 16481 123145369542656 Using SMTP: localhost:25
INFO 2025-10-30 13:04:30,262 email_service 16481 123145369542656 From: aghason.emmanuel@gmail.com
INFO 2025-10-30 13:04:30,265 email_service 16481 123145369542656 Verification code email sent successfully to aghason.emmanuel@gmail.com
INFO 2025-10-30 13:04:30,266 api_views 16481 123145369542656 Verification code sent to aghason.emmanuel@gmail.com
INFO 2025-10-30 13:05:04,460 consumers 16481 4477990400 Market WebSocket disconnected: specific..inmemory!SndWHnIkWrgA
INFO 2025-10-30 13:05:04,684 consumers 16481 4477990400 Market WebSocket connected: specific..inmemory!QzXfJJRMmbpI
INFO 2025-10-30 13:05:05,465 crypto_api_service 16481 123145352216576 CoinGecko: Fetched 283 data points for BTC
INFO 2025-10-30 13:05:16,709 crypto_api_service 16481 123145369542656 CoinGecko API success: fetched 5 coins
INFO 2025-10-30 13:05:16,711 crypto_api_service 16481 123145369542656 Successfully fetched data from _fetch_from_coingecko
INFO 2025-10-30 13:05:16,725 crypto_api_service 16481 123145369542656 Updated 5 cryptocurrencies
INFO 2025-10-30 13:05:31,190 consumers 16481 4477990400 Market WebSocket connected: specific..inmemory!GkeOmifEFEUD
INFO 2025-10-30 13:05:33,053 crypto_api_service 16481 123145352216576 CoinGecko: Fetched 283 data points for BTC
INFO 2025-10-30 13:06:04,300 consumers 16481 4477990400 Market WebSocket disconnected: specific..inmemory!QzXfJJRMmbpI
INFO 2025-10-30 13:06:04,423 consumers 16481 4477990400 Market WebSocket connected: specific..inmemory!GCyfNnjZCEKh
INFO 2025-10-30 13:06:06,683 crypto_api_service 16481 123145352216576 CoinGecko: Fetched 283 data points for BTC
INFO 2025-10-30 13:06:48,464 consumers 16481 4477990400 Market WebSocket disconnected: specific..inmemory!GCyfNnjZCEKh
INFO 2025-10-30 13:06:48,747 consumers 16481 4477990400 Market WebSocket connected: specific..inmemory!ekXhNagsUNlE
INFO 2025-10-30 13:06:49,798 crypto_api_service 16481 123145352216576 CoinGecko: Fetched 283 data points for BTC
INFO 2025-10-30 13:06:53,124 server 16481 4477990400 Killed 3 pending application instances
INFO 2025-10-30 13:06:57,797 autoreload 16672 4512138752 Watching for file changes with StatReloader
WARNING 2025-10-30 13:07:00,179 log 16672 123145450291200 Not Found: /ws/market/
WARNING 2025-10-30 13:07:00,801 log 16672 123145483870208 Not Found: /ws/market/
WARNING 2025-10-30 13:07:01,005 log 16672 123145483870208 Not Found: /ws/market/
WARNING 2025-10-30 13:07:01,032 log 16672 123145500659712 Not Found: /ws/market/
WARNING 2025-10-30 13:07:03,930 log 16672 123145483870208 Not Found: /ws/market/
WARNING 2025-10-30 13:07:04,992 log 16672 123145483870208 Not Found: /ws/market/
WARNING 2025-10-30 13:07:05,003 log 16672 123145500659712 Not Found: /ws/market/
WARNING 2025-10-30 13:07:06,945 log 16672 123145483870208 Not Found: /ws/market/
WARNING 2025-10-30 13:07:08,993 log 16672 123145483870208 Not Found: /ws/market/
WARNING 2025-10-30 13:07:09,003 log 16672 123145500659712 Not Found: /ws/market/
WARNING 2025-10-30 13:07:09,959 log 16672 123145483870208 Not Found: /ws/market/
WARNING 2025-10-30 13:07:12,973 log 16672 123145483870208 Not Found: /ws/market/
WARNING 2025-10-30 13:07:12,993 log 16672 123145483870208 Not Found: /ws/market/
WARNING 2025-10-30 13:07:13,003 log 16672 123145500659712 Not Found: /ws/market/
WARNING 2025-10-30 13:07:15,986 log 16672 123145483870208 Not Found: /ws/market/
WARNING 2025-10-30 13:07:16,995 log 16672 123145483870208 Not Found: /ws/market/
WARNING 2025-10-30 13:07:17,003 log 16672 123145500659712 Not Found: /ws/market/
WARNING 2025-10-30 13:07:19,001 log 16672 123145483870208 Not Found: /ws/market/
WARNING 2025-10-30 13:07:20,991 log 16672 123145483870208 Not Found: /ws/market/
WARNING 2025-10-30 13:07:21,002 log 16672 123145500659712 Not Found: /ws/market/
WARNING 2025-10-30 13:07:22,018 log 16672 123145483870208 Not Found: /ws/market/
WARNING 2025-10-30 13:07:24,993 log 16672 123145483870208 Not Found: /ws/market/
WARNING 2025-10-30 13:07:25,003 log 16672 123145500659712 Not Found: /ws/market/
WARNING 2025-10-30 13:07:25,032 log 16672 123145483870208 Not Found: /ws/market/
WARNING 2025-10-30 13:07:28,045 log 16672 123145483870208 Not Found: /ws/market/
WARNING 2025-10-30 13:07:28,995 log 16672 123145483870208 Not Found: /ws/market/
WARNING 2025-10-30 13:07:29,016 log 16672 123145483870208 Not Found: /ws/market/
WARNING 2025-10-30 13:07:31,061 log 16672 123145483870208 Not Found: /ws/market/
WARNING 2025-10-30 13:07:32,995 log 16672 123145483870208 Not Found: /ws/market/
WARNING 2025-10-30 13:07:33,003 log 16672 123145500659712 Not Found: /ws/market/
WARNING 2025-10-30 13:07:34,074 log 16672 123145483870208 Not Found: /ws/market/
WARNING 2025-10-30 13:07:36,993 log 16672 123145483870208 Not Found: /ws/market/
WARNING 2025-10-30 13:07:37,005 log 16672 123145500659712 Not Found: /ws/market/
WARNING 2025-10-30 13:07:37,089 log 16672 123145483870208 Not Found: /ws/market/
WARNING 2025-10-30 13:07:40,102 log 16672 123145483870208 Not Found: /ws/market/
WARNING 2025-10-30 13:07:40,991 log 16672 123145483870208 Not Found: /ws/market/
WARNING 2025-10-30 13:07:41,001 log 16672 123145500659712 Not Found: /ws/market/
WARNING 2025-10-30 13:07:43,115 log 16672 123145483870208 Not Found: /ws/market/
WARNING 2025-10-30 13:07:44,994 log 16672 123145483870208 Not Found: /ws/market/
WARNING 2025-10-30 13:07:45,005 log 16672 123145500659712 Not Found: /ws/market/
WARNING 2025-10-30 13:07:46,130 log 16672 123145483870208 Not Found: /ws/market/
WARNING 2025-10-30 13:07:48,995 log 16672 123145483870208 Not Found: /ws/market/
WARNING 2025-10-30 13:07:49,005 log 16672 123145500659712 Not Found: /ws/market/
WARNING 2025-10-30 13:07:49,145 log 16672 123145483870208 Not Found: /ws/market/
WARNING 2025-10-30 13:07:52,995 log 16672 123145483870208 Not Found: /ws/market/
WARNING 2025-10-30 13:07:53,017 log 16672 123145483870208 Not Found: /ws/market/
WARNING 2025-10-30 13:07:53,450 log 16672 123145483870208 Not Found: /ws/market/
INFO 2025-10-30 13:07:58,167 cli 16714 4601931264 Starting server at tcp:port=8000:interface=127.0.0.1
INFO 2025-10-30 13:07:58,168 server 16714 4601931264 HTTP/2 support enabled
INFO 2025-10-30 13:07:58,168 server 16714 4601931264 Configuring endpoint tcp:port=8000:interface=127.0.0.1
INFO 2025-10-30 13:07:58,169 server 16714 4601931264 Listening on TCP address 127.0.0.1:8000
INFO 2025-10-30 13:08:00,036 consumers 16714 4601931264 Market WebSocket connected: specific..inmemory!PwXVwbOyNAen
INFO 2025-10-30 13:08:01,785 crypto_api_service 16714 123145385611264 CoinGecko: Fetched 282 data points for BTC
INFO 2025-10-30 13:08:01,802 consumers 16714 4601931264 Market WebSocket connected: specific..inmemory!iiJfFGloPIBn
INFO 2025-10-30 13:08:01,804 consumers 16714 4601931264 Market WebSocket connected: specific..inmemory!yGmvWUtMpwde
INFO 2025-10-30 13:08:02,369 crypto_api_service 16714 123145385611264 CoinGecko: Fetched 282 data points for BTC
INFO 2025-10-30 13:08:02,950 crypto_api_service 16714 123145385611264 CoinGecko: Fetched 282 data points for BTC
INFO 2025-10-30 13:08:03,807 consumers 16714 4601931264 Market WebSocket disconnected: specific..inmemory!PwXVwbOyNAen
INFO 2025-10-30 13:08:03,950 consumers 16714 4601931264 Market WebSocket connected: specific..inmemory!MykDLsGiBdLg
INFO 2025-10-30 13:08:04,747 crypto_api_service 16714 123145385611264 CoinGecko: Fetched 282 data points for BTC
INFO 2025-10-30 13:08:34,218 api_views 16714 123145402937344 Buy API called with data: {'transaction_type': 'BUY', 'cryptocurrency': 'BTC', 'quantity': 3e-05, 'price_per_unit': 108397, 'total_amount': 3.25516191, 'currency': 'USD'}
INFO 2025-10-30 13:08:34,236 api_views 16714 123145402937344 Balance updated for aghason.emmanuel@gmail.com: -3.26 USD, +0.00003000 BTC
INFO 2025-10-30 13:08:34,259 email_service 16714 123145402937344 Attempting to send verification email to aghason.emmanuel@gmail.com
INFO 2025-10-30 13:08:34,260 email_service 16714 123145402937344 Using SMTP: localhost:25
INFO 2025-10-30 13:08:34,260 email_service 16714 123145402937344 From: aghason.emmanuel@gmail.com
INFO 2025-10-30 13:08:34,398 email_service 16714 123145402937344 Verification code email sent successfully to aghason.emmanuel@gmail.com
INFO 2025-10-30 13:08:34,399 api_views 16714 123145402937344 Verification code sent to aghason.emmanuel@gmail.com
INFO 2025-10-30 13:09:08,811 consumers 16714 4601931264 Market WebSocket disconnected: specific..inmemory!MykDLsGiBdLg
INFO 2025-10-30 13:09:09,008 consumers 16714 4601931264 Market WebSocket connected: specific..inmemory!tjkLKEztAshj
INFO 2025-10-30 13:09:09,961 crypto_api_service 16714 123145385611264 CoinGecko: Fetched 283 data points for BTC
INFO 2025-10-30 13:09:24,236 crypto_api_service 16714 123145402937344 CoinGecko API success: fetched 5 coins
INFO 2025-10-30 13:09:24,240 crypto_api_service 16714 123145402937344 Successfully fetched data from _fetch_from_coingecko
INFO 2025-10-30 13:09:24,257 crypto_api_service 16714 123145402937344 Updated 5 cryptocurrencies
INFO 2025-10-30 13:09:25,086 consumers 16714 4601931264 Market WebSocket disconnected: specific..inmemory!iiJfFGloPIBn
INFO 2025-10-30 13:11:05,295 api_views 16714 123145402937344 Buy API called with data: {'transaction_type': 'BUY', 'cryptocurrency': 'BTC', 'quantity': 0.005, 'price_per_unit': 108397, 'total_amount': 542.526985, 'currency': 'USD'}
INFO 2025-10-30 13:11:05,306 api_views 16714 123145402937344 Balance updated for aghason.emmanuel@gmail.com: -542.53 USD, +0.00500000 BTC
INFO 2025-10-30 13:11:05,319 email_service 16714 123145402937344 Attempting to send verification email to aghason.emmanuel@gmail.com
INFO 2025-10-30 13:11:05,319 email_service 16714 123145402937344 Using SMTP: localhost:25
INFO 2025-10-30 13:11:05,319 email_service 16714 123145402937344 From: aghason.emmanuel@gmail.com
INFO 2025-10-30 13:11:05,321 email_service 16714 123145402937344 Verification code email sent successfully to aghason.emmanuel@gmail.com
INFO 2025-10-30 13:11:05,321 api_views 16714 123145402937344 Verification code sent to aghason.emmanuel@gmail.com
INFO 2025-10-30 13:11:28,416 consumers 16714 4601931264 Market WebSocket disconnected: specific..inmemory!tjkLKEztAshj
INFO 2025-10-30 13:11:29,650 consumers 16714 4601931264 Market WebSocket connected: specific..inmemory!VOCDisciRHEf
INFO 2025-10-30 13:11:30,540 crypto_api_service 16714 123145385611264 CoinGecko: Fetched 283 data points for BTC
INFO 2025-10-30 13:11:35,992 crypto_api_service 16714 123145402937344 CoinGecko API success: fetched 5 coins
INFO 2025-10-30 13:11:35,994 crypto_api_service 16714 123145402937344 Successfully fetched data from _fetch_from_coingecko
INFO 2025-10-30 13:11:36,011 crypto_api_service 16714 123145402937344 Updated 5 cryptocurrencies
INFO 2025-10-30 13:14:55,212 crypto_api_service 16714 123145402937344 CoinGecko API success: fetched 5 coins
INFO 2025-10-30 13:14:55,215 crypto_api_service 16714 123145402937344 Successfully fetched data from _fetch_from_coingecko
INFO 2025-10-30 13:14:55,236 crypto_api_service 16714 123145402937344 Updated 5 cryptocurrencies
INFO 2025-10-30 13:18:48,558 crypto_api_service 16714 123145402937344 CoinGecko API success: fetched 5 coins
INFO 2025-10-30 13:18:48,563 crypto_api_service 16714 123145402937344 Successfully fetched data from _fetch_from_coingecko
INFO 2025-10-30 13:18:48,589 crypto_api_service 16714 123145402937344 Updated 5 cryptocurrencies
INFO 2025-10-30 13:19:59,969 api_views 16714 123145402937344 Buy API called with data: {'transaction_type': 'BUY', 'cryptocurrency': 'ETH', 'quantity': 0.005, 'price_per_unit': 3828.55, 'total_amount': 19.161892750000003, 'currency': 'USD'}
INFO 2025-10-30 13:19:59,984 api_views 16714 123145402937344 Balance updated for aghason.emmanuel@gmail.com: -19.16 USD, +0.00500000 ETH
INFO 2025-10-30 13:19:59,996 email_service 16714 123145402937344 Attempting to send verification email to aghason.emmanuel@gmail.com
INFO 2025-10-30 13:19:59,996 email_service 16714 123145402937344 Using SMTP: localhost:25
INFO 2025-10-30 13:19:59,997 email_service 16714 123145402937344 From: aghason.emmanuel@gmail.com
INFO 2025-10-30 13:20:00,000 email_service 16714 123145402937344 Verification code email sent successfully to aghason.emmanuel@gmail.com
INFO 2025-10-30 13:20:00,001 api_views 16714 123145402937344 Verification code sent to aghason.emmanuel@gmail.com
INFO 2025-10-30 13:20:32,401 consumers 16714 4601931264 Market WebSocket disconnected: specific..inmemory!VOCDisciRHEf
INFO 2025-10-30 13:20:33,065 consumers 16714 4601931264 Market WebSocket connected: specific..inmemory!tDNbIOABPAwT
INFO 2025-10-30 13:20:34,781 crypto_api_service 16714 123145385611264 CoinGecko: Fetched 283 data points for BTC
INFO 2025-10-30 13:20:52,745 api_views 16714 123145402937344 Buy API called with data: {'transaction_type': 'BUY', 'cryptocurrency': 'TRX', 'quantity': 4, 'price_per_unit': 0.293065, 'total_amount': 1.17343226, 'currency': 'USD'}
INFO 2025-10-30 13:20:52,759 api_views 16714 123145402937344 Balance updated for aghason.emmanuel@gmail.com: -1.17 USD, +4.00000000 TRX
INFO 2025-10-30 13:20:52,768 email_service 16714 123145402937344 Attempting to send verification email to aghason.emmanuel@gmail.com
INFO 2025-10-30 13:20:52,768 email_service 16714 123145402937344 Using SMTP: localhost:25
INFO 2025-10-30 13:20:52,768 email_service 16714 123145402937344 From: aghason.emmanuel@gmail.com
INFO 2025-10-30 13:20:52,771 email_service 16714 123145402937344 Verification code email sent successfully to aghason.emmanuel@gmail.com
INFO 2025-10-30 13:20:52,772 api_views 16714 123145402937344 Verification code sent to aghason.emmanuel@gmail.com
INFO 2025-10-30 13:21:18,359 consumers 16714 4601931264 Market WebSocket disconnected: specific..inmemory!tDNbIOABPAwT
INFO 2025-10-30 13:21:18,573 consumers 16714 4601931264 Market WebSocket connected: specific..inmemory!mHihMyhPvPXP
INFO 2025-10-30 13:21:19,325 crypto_api_service 16714 123145385611264 CoinGecko: Fetched 283 data points for BTC
INFO 2025-10-30 13:21:31,513 crypto_api_service 16714 123145402937344 CoinGecko API success: fetched 5 coins
INFO 2025-10-30 13:21:31,518 crypto_api_service 16714 123145402937344 Successfully fetched data from _fetch_from_coingecko
INFO 2025-10-30 13:21:31,547 crypto_api_service 16714 123145402937344 Updated 5 cryptocurrencies
INFO 2025-10-30 13:21:45,079 crypto_api_service 16714 123145402937344 CoinGecko API success: fetched 5 coins
INFO 2025-10-30 13:21:45,081 crypto_api_service 16714 123145402937344 Successfully fetched data from _fetch_from_coingecko
INFO 2025-10-30 13:21:45,098 crypto_api_service 16714 123145402937344 Updated 5 cryptocurrencies
INFO 2025-10-30 13:22:20,968 api_views 16714 123145402937344 Buy API called with data: {'transaction_type': 'BUY', 'cryptocurrency': 'LTC', 'quantity': 1, 'price_per_unit': 95.3, 'total_amount': 95.39529999999999, 'currency': 'USD'}
INFO 2025-10-30 13:22:20,975 api_views 16714 123145402937344 Balance updated for aghason.emmanuel@gmail.com: -95.40 USD, +1.00000000 LTC
INFO 2025-10-30 13:22:20,982 email_service 16714 123145402937344 Attempting to send verification email to aghason.emmanuel@gmail.com
INFO 2025-10-30 13:22:20,982 email_service 16714 123145402937344 Using SMTP: localhost:25
INFO 2025-10-30 13:22:20,982 email_service 16714 123145402937344 From: aghason.emmanuel@gmail.com
INFO 2025-10-30 13:22:20,988 email_service 16714 123145402937344 Verification code email sent successfully to aghason.emmanuel@gmail.com
INFO 2025-10-30 13:22:20,988 api_views 16714 123145402937344 Verification code sent to aghason.emmanuel@gmail.com
INFO 2025-10-30 13:22:44,249 consumers 16714 4601931264 Market WebSocket disconnected: specific..inmemory!mHihMyhPvPXP
INFO 2025-10-30 13:22:44,824 consumers 16714 4601931264 Market WebSocket connected: specific..inmemory!JPqNIlqKIrek
INFO 2025-10-30 13:22:45,562 crypto_api_service 16714 123145385611264 CoinGecko: Fetched 283 data points for BTC
INFO 2025-10-30 13:22:57,351 crypto_api_service 16714 123145402937344 CoinGecko API success: fetched 5 coins
INFO 2025-10-30 13:22:57,355 crypto_api_service 16714 123145402937344 Successfully fetched data from _fetch_from_coingecko
INFO 2025-10-30 13:22:57,369 crypto_api_service 16714 123145402937344 Updated 5 cryptocurrencies
INFO 2025-10-30 13:23:15,131 server 16714 4601931264 Killed 2 pending application instances
INFO 2025-10-30 13:23:20,535 autoreload 17179 4552893952 Watching for file changes with StatReloader
WARNING 2025-10-30 13:23:22,025 log 17179 123145412431872 Not Found: /ws/market/
INFO 2025-10-30 13:23:22,407 crypto_api_service 17179 123145377779712 CoinGecko API success: fetched 5 coins
INFO 2025-10-30 13:23:22,411 crypto_api_service 17179 123145377779712 Successfully fetched data from _fetch_from_coingecko
INFO 2025-10-30 13:23:22,429 crypto_api_service 17179 123145377779712 Updated 5 cryptocurrencies
WARNING 2025-10-30 13:23:23,035 log 17179 123145412431872 Not Found: /ws/market/
WARNING 2025-10-30 13:23:26,029 log 17179 123145412431872 Not Found: /ws/market/
WARNING 2025-10-30 13:23:27,027 log 17179 123145411895296 Not Found: /ws/market/
INFO 2025-10-30 13:23:33,855 cli 17195 4574504448 Starting server at tcp:port=8000:interface=127.0.0.1
INFO 2025-10-30 13:23:33,855 server 17195 4574504448 HTTP/2 support enabled
INFO 2025-10-30 13:23:33,856 server 17195 4574504448 Configuring endpoint tcp:port=8000:interface=127.0.0.1
INFO 2025-10-30 13:23:33,860 server 17195 4574504448 Listening on TCP address 127.0.0.1:8000
INFO 2025-10-30 13:23:34,033 consumers 17195 4574504448 Market WebSocket connected: specific..inmemory!UhtygLBtntwj
INFO 2025-10-30 13:23:34,809 crypto_api_service 17195 123145347977216 CoinGecko: Fetched 282 data points for BTC
INFO 2025-10-30 13:23:35,029 consumers 17195 4574504448 Market WebSocket connected: specific..inmemory!AMnxMlihUcyL
INFO 2025-10-30 13:23:35,946 crypto_api_service 17195 123145347977216 CoinGecko: Fetched 282 data points for BTC
INFO 2025-10-30 13:24:01,205 api_views 17195 123145365303296 Buy API called with data: {'transaction_type': 'BUY', 'cryptocurrency': 'LTC', 'quantity': 5, 'price_per_unit': 95.1, 'total_amount': 475.9755, 'currency': 'USD'}
INFO 2025-10-30 13:24:01,214 api_views 17195 123145365303296 Balance updated for aghason.emmanuel@gmail.com: -475.98 USD, +5.00000000 LTC
INFO 2025-10-30 13:24:01,255 email_service 17195 123145365303296 Attempting to send verification email to aghason.emmanuel@gmail.com
INFO 2025-10-30 13:24:01,255 email_service 17195 123145365303296 Using SMTP: localhost:25
INFO 2025-10-30 13:24:01,256 email_service 17195 123145365303296 From: aghason.emmanuel@gmail.com
INFO 2025-10-30 13:24:01,428 email_service 17195 123145365303296 Verification code email sent successfully to aghason.emmanuel@gmail.com
INFO 2025-10-30 13:24:01,428 api_views 17195 123145365303296 Verification code sent to aghason.emmanuel@gmail.com
INFO 2025-10-30 13:24:21,182 consumers 17195 4574504448 Market WebSocket disconnected: specific..inmemory!UhtygLBtntwj
INFO 2025-10-30 13:24:21,284 consumers 17195 4574504448 Market WebSocket connected: specific..inmemory!HxvuhFtOBoww
INFO 2025-10-30 13:24:22,292 crypto_api_service 17195 123145347977216 CoinGecko: Fetched 282 data points for BTC
INFO 2025-10-30 13:24:27,773 crypto_api_service 17195 123145365303296 CoinGecko API success: fetched 5 coins
INFO 2025-10-30 13:24:27,776 crypto_api_service 17195 123145365303296 Successfully fetched data from _fetch_from_coingecko
INFO 2025-10-30 13:24:27,797 crypto_api_service 17195 123145365303296 Updated 5 cryptocurrencies
INFO 2025-10-30 13:24:35,721 consumers 17195 4574504448 Market WebSocket disconnected: specific..inmemory!HxvuhFtOBoww
INFO 2025-10-30 13:24:39,164 consumers 17195 4574504448 Market WebSocket connected: specific..inmemory!qszZKBpSvVSv
INFO 2025-10-30 13:24:41,465 crypto_api_service 17195 123145347977216 CoinGecko: Fetched 282 data points for BTC
INFO 2025-10-30 13:24:49,034 crypto_api_service 17195 123145365303296 CoinGecko API success: fetched 5 coins
INFO 2025-10-30 13:24:49,037 crypto_api_service 17195 123145365303296 Successfully fetched data from _fetch_from_coingecko
INFO 2025-10-30 13:24:49,052 crypto_api_service 17195 123145365303296 Updated 5 cryptocurrencies
INFO 2025-10-30 13:25:17,471 api_views 17195 123145365303296 Buy API called with data: {'transaction_type': 'BUY', 'cryptocurrency': 'TRX', 'quantity': 50, 'price_per_unit': 0.292822, 'total_amount': 14.655741100000002, 'currency': 'USD'}
INFO 2025-10-30 13:25:17,484 api_views 17195 123145365303296 Balance updated for aghason.emmanuel@gmail.com: -14.66 USD, +50.00000000 TRX
INFO 2025-10-30 13:25:17,493 email_service 17195 123145365303296 Attempting to send verification email to aghason.emmanuel@gmail.com
INFO 2025-10-30 13:25:17,493 email_service 17195 123145365303296 Using SMTP: localhost:25
INFO 2025-10-30 13:25:17,493 email_service 17195 123145365303296 From: aghason.emmanuel@gmail.com
INFO 2025-10-30 13:25:17,497 email_service 17195 123145365303296 Verification code email sent successfully to aghason.emmanuel@gmail.com
INFO 2025-10-30 13:25:17,498 api_views 17195 123145365303296 Verification code sent to aghason.emmanuel@gmail.com
INFO 2025-10-30 13:25:35,830 consumers 17195 4574504448 Market WebSocket disconnected: specific..inmemory!qszZKBpSvVSv
INFO 2025-10-30 13:25:36,010 consumers 17195 4574504448 Market WebSocket connected: specific..inmemory!OXZoUzCQAiVx
INFO 2025-10-30 13:25:37,002 crypto_api_service 17195 123145347977216 CoinGecko: Fetched 283 data points for BTC
INFO 2025-10-30 13:25:46,690 crypto_api_service 17195 123145365303296 CoinGecko API success: fetched 5 coins
INFO 2025-10-30 13:25:46,693 crypto_api_service 17195 123145365303296 Successfully fetched data from _fetch_from_coingecko
INFO 2025-10-30 13:25:46,708 crypto_api_service 17195 123145365303296 Updated 5 cryptocurrencies
INFO 2025-10-30 13:26:14,167 api_views 17195 123145365303296 Buy API called with data: {'transaction_type': 'BUY', 'cryptocurrency': 'USDT', 'quantity': 200, 'price_per_unit': 1, 'total_amount': 200.2, 'currency': 'USD'}
INFO 2025-10-30 13:26:14,173 api_views 17195 123145365303296 Balance updated for aghason.emmanuel@gmail.com: -200.20 USD, +200.00000000 USDT
INFO 2025-10-30 13:26:14,182 email_service 17195 123145365303296 Attempting to send verification email to aghason.emmanuel@gmail.com
INFO 2025-10-30 13:26:14,182 email_service 17195 123145365303296 Using SMTP: localhost:25
INFO 2025-10-30 13:26:14,183 email_service 17195 123145365303296 From: aghason.emmanuel@gmail.com
INFO 2025-10-30 13:26:14,186 email_service 17195 123145365303296 Verification code email sent successfully to aghason.emmanuel@gmail.com
INFO 2025-10-30 13:26:14,187 api_views 17195 123145365303296 Verification code sent to aghason.emmanuel@gmail.com
INFO 2025-10-30 13:26:35,838 consumers 17195 4574504448 Market WebSocket disconnected: specific..inmemory!OXZoUzCQAiVx
INFO 2025-10-30 13:26:35,955 consumers 17195 4574504448 Market WebSocket connected: specific..inmemory!qDHdkzEUYEls
INFO 2025-10-30 13:26:38,968 crypto_api_service 17195 123145347977216 CoinGecko: Fetched 283 data points for BTC
INFO 2025-10-30 13:26:43,392 crypto_api_service 17195 123145365303296 CoinGecko API success: fetched 5 coins
INFO 2025-10-30 13:26:43,396 crypto_api_service 17195 123145365303296 Successfully fetched data from _fetch_from_coingecko
INFO 2025-10-30 13:26:43,411 crypto_api_service 17195 123145365303296 Updated 5 cryptocurrencies
INFO 2025-10-30 13:27:17,715 api_views 17195 123145365303296 Buy API called with data: {'transaction_type': 'BUY', 'cryptocurrency': 'ETH', 'quantity': 1.00000006, 'price_per_unit': 3810.75, 'total_amount': 3814.560978873645, 'currency': 'USD'}
INFO 2025-10-30 13:27:17,723 api_views 17195 123145365303296 Balance updated for aghason.emmanuel@gmail.com: -3814.56 USD, +1.00000006 ETH
INFO 2025-10-30 13:27:17,731 email_service 17195 123145365303296 Attempting to send verification email to aghason.emmanuel@gmail.com
INFO 2025-10-30 13:27:17,732 email_service 17195 123145365303296 Using SMTP: localhost:25
INFO 2025-10-30 13:27:17,732 email_service 17195 123145365303296 From: aghason.emmanuel@gmail.com
INFO 2025-10-30 13:27:17,738 email_service 17195 123145365303296 Verification code email sent successfully to aghason.emmanuel@gmail.com
INFO 2025-10-30 13:27:17,739 api_views 17195 123145365303296 Verification code sent to aghason.emmanuel@gmail.com
INFO 2025-10-30 13:27:38,927 consumers 17195 4574504448 Market WebSocket disconnected: specific..inmemory!qDHdkzEUYEls
INFO 2025-10-30 13:27:39,097 consumers 17195 4574504448 Market WebSocket connected: specific..inmemory!bRWWJLVPcrCj
INFO 2025-10-30 13:27:42,932 crypto_api_service 17195 123145347977216 CoinGecko: Fetched 283 data points for BTC
INFO 2025-10-30 13:27:51,907 crypto_api_service 17195 123145365303296 CoinGecko API success: fetched 5 coins
INFO 2025-10-30 13:27:51,911 crypto_api_service 17195 123145365303296 Successfully fetched data from _fetch_from_coingecko
INFO 2025-10-30 13:27:51,925 crypto_api_service 17195 123145365303296 Updated 5 cryptocurrencies
INFO 2025-10-30 13:27:58,601 crypto_api_service 17195 123145365303296 CoinGecko API success: fetched 5 coins
INFO 2025-10-30 13:27:58,605 crypto_api_service 17195 123145365303296 Successfully fetched data from _fetch_from_coingecko
INFO 2025-10-30 13:27:58,622 crypto_api_service 17195 123145365303296 Updated 5 cryptocurrencies
INFO 2025-10-30 13:28:39,729 api_views 17195 123145365303296 Buy API called with data: {'transaction_type': 'BUY', 'cryptocurrency': 'BTC', 'quantity': 0.005, 'price_per_unit': 108357, 'total_amount': 542.326785, 'currency': 'USD'}
INFO 2025-10-30 13:28:39,740 api_views 17195 123145365303296 Balance updated for aghason.emmanuel@gmail.com: -542.33 USD, +0.00500000 BTC
INFO 2025-10-30 13:28:39,745 email_service 17195 123145365303296 Attempting to send verification email to aghason.emmanuel@gmail.com
INFO 2025-10-30 13:28:39,746 email_service 17195 123145365303296 Using SMTP: localhost:25
INFO 2025-10-30 13:28:39,750 email_service 17195 123145365303296 From: aghason.emmanuel@gmail.com
INFO 2025-10-30 13:28:39,752 email_service 17195 123145365303296 Verification code email sent successfully to aghason.emmanuel@gmail.com
INFO 2025-10-30 13:28:39,752 api_views 17195 123145365303296 Verification code sent to aghason.emmanuel@gmail.com
INFO 2025-10-30 13:29:01,821 consumers 17195 4574504448 Market WebSocket disconnected: specific..inmemory!bRWWJLVPcrCj
INFO 2025-10-30 13:29:02,389 consumers 17195 4574504448 Market WebSocket connected: specific..inmemory!dtzkoZNGbTgL
INFO 2025-10-30 13:29:03,455 crypto_api_service 17195 123145347977216 CoinGecko: Fetched 283 data points for BTC
INFO 2025-10-30 13:29:12,189 crypto_api_service 17195 123145365303296 CoinGecko API success: fetched 5 coins
INFO 2025-10-30 13:29:12,192 crypto_api_service 17195 123145365303296 Successfully fetched data from _fetch_from_coingecko
INFO 2025-10-30 13:29:12,203 crypto_api_service 17195 123145365303296 Updated 5 cryptocurrencies
INFO 2025-10-30 13:31:14,875 crypto_api_service 17195 123145365303296 CoinGecko API success: fetched 5 coins
INFO 2025-10-30 13:31:14,878 crypto_api_service 17195 123145365303296 Successfully fetched data from _fetch_from_coingecko
INFO 2025-10-30 13:31:14,901 crypto_api_service 17195 123145365303296 Updated 5 cryptocurrencies
ERROR 2025-10-30 13:34:36,308 server 17195 4574504448 Exception inside application: No route found for path 'ws/portfolio/'.
Traceback (most recent call last):
  File "/Users/emmidev/.pyenv/versions/3.11.8/lib/python3.11/site-packages/channels/routing.py", line 48, in __call__
    return await application(scope, receive, send)
           ^^^^^^^^^^^^^^^^^^^^^^^^^^^^^^^^^^^^^^^
  File "/Users/emmidev/.pyenv/versions/3.11.8/lib/python3.11/site-packages/channels/sessions.py", line 44, in __call__
    return await self.inner(dict(scope, cookies=cookies), receive, send)
           ^^^^^^^^^^^^^^^^^^^^^^^^^^^^^^^^^^^^^^^^^^^^^^^^^^^^^^^^^^^^^
  File "/Users/emmidev/.pyenv/versions/3.11.8/lib/python3.11/site-packages/channels/sessions.py", line 261, in __call__
    return await self.inner(wrapper.scope, receive, wrapper.send)
           ^^^^^^^^^^^^^^^^^^^^^^^^^^^^^^^^^^^^^^^^^^^^^^^^^^^^^^
  File "/Users/emmidev/.pyenv/versions/3.11.8/lib/python3.11/site-packages/channels/auth.py", line 185, in __call__
    return await super().__call__(scope, receive, send)
           ^^^^^^^^^^^^^^^^^^^^^^^^^^^^^^^^^^^^^^^^^^^^
  File "/Users/emmidev/.pyenv/versions/3.11.8/lib/python3.11/site-packages/channels/middleware.py", line 24, in __call__
    return await self.inner(scope, receive, send)
           ^^^^^^^^^^^^^^^^^^^^^^^^^^^^^^^^^^^^^^
  File "/Users/emmidev/.pyenv/versions/3.11.8/lib/python3.11/site-packages/channels/routing.py", line 136, in __call__
    raise ValueError("No route found for path %r." % path)
ValueError: No route found for path 'ws/portfolio/'.
INFO 2025-10-30 13:34:36,898 crypto_api_service 17195 123145365303296 CoinGecko API success: fetched 5 coins
INFO 2025-10-30 13:34:36,906 crypto_api_service 17195 123145365303296 Successfully fetched data from _fetch_from_coingecko
INFO 2025-10-30 13:34:36,967 crypto_api_service 17195 123145365303296 Updated 5 cryptocurrencies
ERROR 2025-10-30 13:34:37,318 server 17195 4574504448 Exception inside application: No route found for path 'ws/portfolio/'.
Traceback (most recent call last):
  File "/Users/emmidev/.pyenv/versions/3.11.8/lib/python3.11/site-packages/channels/routing.py", line 48, in __call__
    return await application(scope, receive, send)
           ^^^^^^^^^^^^^^^^^^^^^^^^^^^^^^^^^^^^^^^
  File "/Users/emmidev/.pyenv/versions/3.11.8/lib/python3.11/site-packages/channels/sessions.py", line 44, in __call__
    return await self.inner(dict(scope, cookies=cookies), receive, send)
           ^^^^^^^^^^^^^^^^^^^^^^^^^^^^^^^^^^^^^^^^^^^^^^^^^^^^^^^^^^^^^
  File "/Users/emmidev/.pyenv/versions/3.11.8/lib/python3.11/site-packages/channels/sessions.py", line 261, in __call__
    return await self.inner(wrapper.scope, receive, wrapper.send)
           ^^^^^^^^^^^^^^^^^^^^^^^^^^^^^^^^^^^^^^^^^^^^^^^^^^^^^^
  File "/Users/emmidev/.pyenv/versions/3.11.8/lib/python3.11/site-packages/channels/auth.py", line 185, in __call__
    return await super().__call__(scope, receive, send)
           ^^^^^^^^^^^^^^^^^^^^^^^^^^^^^^^^^^^^^^^^^^^^
  File "/Users/emmidev/.pyenv/versions/3.11.8/lib/python3.11/site-packages/channels/middleware.py", line 24, in __call__
    return await self.inner(scope, receive, send)
           ^^^^^^^^^^^^^^^^^^^^^^^^^^^^^^^^^^^^^^
  File "/Users/emmidev/.pyenv/versions/3.11.8/lib/python3.11/site-packages/channels/routing.py", line 136, in __call__
    raise ValueError("No route found for path %r." % path)
ValueError: No route found for path 'ws/portfolio/'.
ERROR 2025-10-30 13:34:42,429 server 17195 4574504448 Exception inside application: No route found for path 'ws/portfolio/'.
Traceback (most recent call last):
  File "/Users/emmidev/.pyenv/versions/3.11.8/lib/python3.11/site-packages/channels/routing.py", line 48, in __call__
    return await application(scope, receive, send)
           ^^^^^^^^^^^^^^^^^^^^^^^^^^^^^^^^^^^^^^^
  File "/Users/emmidev/.pyenv/versions/3.11.8/lib/python3.11/site-packages/channels/sessions.py", line 44, in __call__
    return await self.inner(dict(scope, cookies=cookies), receive, send)
           ^^^^^^^^^^^^^^^^^^^^^^^^^^^^^^^^^^^^^^^^^^^^^^^^^^^^^^^^^^^^^
  File "/Users/emmidev/.pyenv/versions/3.11.8/lib/python3.11/site-packages/channels/sessions.py", line 261, in __call__
    return await self.inner(wrapper.scope, receive, wrapper.send)
           ^^^^^^^^^^^^^^^^^^^^^^^^^^^^^^^^^^^^^^^^^^^^^^^^^^^^^^
  File "/Users/emmidev/.pyenv/versions/3.11.8/lib/python3.11/site-packages/channels/auth.py", line 185, in __call__
    return await super().__call__(scope, receive, send)
           ^^^^^^^^^^^^^^^^^^^^^^^^^^^^^^^^^^^^^^^^^^^^
  File "/Users/emmidev/.pyenv/versions/3.11.8/lib/python3.11/site-packages/channels/middleware.py", line 24, in __call__
    return await self.inner(scope, receive, send)
           ^^^^^^^^^^^^^^^^^^^^^^^^^^^^^^^^^^^^^^
  File "/Users/emmidev/.pyenv/versions/3.11.8/lib/python3.11/site-packages/channels/routing.py", line 136, in __call__
    raise ValueError("No route found for path %r." % path)
ValueError: No route found for path 'ws/portfolio/'.
ERROR 2025-10-30 13:34:43,433 server 17195 4574504448 Exception inside application: No route found for path 'ws/portfolio/'.
Traceback (most recent call last):
  File "/Users/emmidev/.pyenv/versions/3.11.8/lib/python3.11/site-packages/channels/routing.py", line 48, in __call__
    return await application(scope, receive, send)
           ^^^^^^^^^^^^^^^^^^^^^^^^^^^^^^^^^^^^^^^
  File "/Users/emmidev/.pyenv/versions/3.11.8/lib/python3.11/site-packages/channels/sessions.py", line 44, in __call__
    return await self.inner(dict(scope, cookies=cookies), receive, send)
           ^^^^^^^^^^^^^^^^^^^^^^^^^^^^^^^^^^^^^^^^^^^^^^^^^^^^^^^^^^^^^
  File "/Users/emmidev/.pyenv/versions/3.11.8/lib/python3.11/site-packages/channels/sessions.py", line 261, in __call__
    return await self.inner(wrapper.scope, receive, wrapper.send)
           ^^^^^^^^^^^^^^^^^^^^^^^^^^^^^^^^^^^^^^^^^^^^^^^^^^^^^^
  File "/Users/emmidev/.pyenv/versions/3.11.8/lib/python3.11/site-packages/channels/auth.py", line 185, in __call__
    return await super().__call__(scope, receive, send)
           ^^^^^^^^^^^^^^^^^^^^^^^^^^^^^^^^^^^^^^^^^^^^
  File "/Users/emmidev/.pyenv/versions/3.11.8/lib/python3.11/site-packages/channels/middleware.py", line 24, in __call__
    return await self.inner(scope, receive, send)
           ^^^^^^^^^^^^^^^^^^^^^^^^^^^^^^^^^^^^^^
  File "/Users/emmidev/.pyenv/versions/3.11.8/lib/python3.11/site-packages/channels/routing.py", line 136, in __call__
    raise ValueError("No route found for path %r." % path)
ValueError: No route found for path 'ws/portfolio/'.
ERROR 2025-10-30 13:34:47,453 server 17195 4574504448 Exception inside application: No route found for path 'ws/portfolio/'.
Traceback (most recent call last):
  File "/Users/emmidev/.pyenv/versions/3.11.8/lib/python3.11/site-packages/channels/routing.py", line 48, in __call__
    return await application(scope, receive, send)
           ^^^^^^^^^^^^^^^^^^^^^^^^^^^^^^^^^^^^^^^
  File "/Users/emmidev/.pyenv/versions/3.11.8/lib/python3.11/site-packages/channels/sessions.py", line 44, in __call__
    return await self.inner(dict(scope, cookies=cookies), receive, send)
           ^^^^^^^^^^^^^^^^^^^^^^^^^^^^^^^^^^^^^^^^^^^^^^^^^^^^^^^^^^^^^
  File "/Users/emmidev/.pyenv/versions/3.11.8/lib/python3.11/site-packages/channels/sessions.py", line 261, in __call__
    return await self.inner(wrapper.scope, receive, wrapper.send)
           ^^^^^^^^^^^^^^^^^^^^^^^^^^^^^^^^^^^^^^^^^^^^^^^^^^^^^^
  File "/Users/emmidev/.pyenv/versions/3.11.8/lib/python3.11/site-packages/channels/auth.py", line 185, in __call__
    return await super().__call__(scope, receive, send)
           ^^^^^^^^^^^^^^^^^^^^^^^^^^^^^^^^^^^^^^^^^^^^
  File "/Users/emmidev/.pyenv/versions/3.11.8/lib/python3.11/site-packages/channels/middleware.py", line 24, in __call__
    return await self.inner(scope, receive, send)
           ^^^^^^^^^^^^^^^^^^^^^^^^^^^^^^^^^^^^^^
  File "/Users/emmidev/.pyenv/versions/3.11.8/lib/python3.11/site-packages/channels/routing.py", line 136, in __call__
    raise ValueError("No route found for path %r." % path)
ValueError: No route found for path 'ws/portfolio/'.
ERROR 2025-10-30 13:34:48,459 server 17195 4574504448 Exception inside application: No route found for path 'ws/portfolio/'.
Traceback (most recent call last):
  File "/Users/emmidev/.pyenv/versions/3.11.8/lib/python3.11/site-packages/channels/routing.py", line 48, in __call__
    return await application(scope, receive, send)
           ^^^^^^^^^^^^^^^^^^^^^^^^^^^^^^^^^^^^^^^
  File "/Users/emmidev/.pyenv/versions/3.11.8/lib/python3.11/site-packages/channels/sessions.py", line 44, in __call__
    return await self.inner(dict(scope, cookies=cookies), receive, send)
           ^^^^^^^^^^^^^^^^^^^^^^^^^^^^^^^^^^^^^^^^^^^^^^^^^^^^^^^^^^^^^
  File "/Users/emmidev/.pyenv/versions/3.11.8/lib/python3.11/site-packages/channels/sessions.py", line 261, in __call__
    return await self.inner(wrapper.scope, receive, wrapper.send)
           ^^^^^^^^^^^^^^^^^^^^^^^^^^^^^^^^^^^^^^^^^^^^^^^^^^^^^^
  File "/Users/emmidev/.pyenv/versions/3.11.8/lib/python3.11/site-packages/channels/auth.py", line 185, in __call__
    return await super().__call__(scope, receive, send)
           ^^^^^^^^^^^^^^^^^^^^^^^^^^^^^^^^^^^^^^^^^^^^
  File "/Users/emmidev/.pyenv/versions/3.11.8/lib/python3.11/site-packages/channels/middleware.py", line 24, in __call__
    return await self.inner(scope, receive, send)
           ^^^^^^^^^^^^^^^^^^^^^^^^^^^^^^^^^^^^^^
  File "/Users/emmidev/.pyenv/versions/3.11.8/lib/python3.11/site-packages/channels/routing.py", line 136, in __call__
    raise ValueError("No route found for path %r." % path)
ValueError: No route found for path 'ws/portfolio/'.
ERROR 2025-10-30 13:34:53,466 server 17195 4574504448 Exception inside application: No route found for path 'ws/portfolio/'.
Traceback (most recent call last):
  File "/Users/emmidev/.pyenv/versions/3.11.8/lib/python3.11/site-packages/channels/routing.py", line 48, in __call__
    return await application(scope, receive, send)
           ^^^^^^^^^^^^^^^^^^^^^^^^^^^^^^^^^^^^^^^
  File "/Users/emmidev/.pyenv/versions/3.11.8/lib/python3.11/site-packages/channels/sessions.py", line 44, in __call__
    return await self.inner(dict(scope, cookies=cookies), receive, send)
           ^^^^^^^^^^^^^^^^^^^^^^^^^^^^^^^^^^^^^^^^^^^^^^^^^^^^^^^^^^^^^
  File "/Users/emmidev/.pyenv/versions/3.11.8/lib/python3.11/site-packages/channels/sessions.py", line 261, in __call__
    return await self.inner(wrapper.scope, receive, wrapper.send)
           ^^^^^^^^^^^^^^^^^^^^^^^^^^^^^^^^^^^^^^^^^^^^^^^^^^^^^^
  File "/Users/emmidev/.pyenv/versions/3.11.8/lib/python3.11/site-packages/channels/auth.py", line 185, in __call__
    return await super().__call__(scope, receive, send)
           ^^^^^^^^^^^^^^^^^^^^^^^^^^^^^^^^^^^^^^^^^^^^
  File "/Users/emmidev/.pyenv/versions/3.11.8/lib/python3.11/site-packages/channels/middleware.py", line 24, in __call__
    return await self.inner(scope, receive, send)
           ^^^^^^^^^^^^^^^^^^^^^^^^^^^^^^^^^^^^^^
  File "/Users/emmidev/.pyenv/versions/3.11.8/lib/python3.11/site-packages/channels/routing.py", line 136, in __call__
    raise ValueError("No route found for path %r." % path)
ValueError: No route found for path 'ws/portfolio/'.
ERROR 2025-10-30 13:34:54,470 server 17195 4574504448 Exception inside application: No route found for path 'ws/portfolio/'.
Traceback (most recent call last):
  File "/Users/emmidev/.pyenv/versions/3.11.8/lib/python3.11/site-packages/channels/routing.py", line 48, in __call__
    return await application(scope, receive, send)
           ^^^^^^^^^^^^^^^^^^^^^^^^^^^^^^^^^^^^^^^
  File "/Users/emmidev/.pyenv/versions/3.11.8/lib/python3.11/site-packages/channels/sessions.py", line 44, in __call__
    return await self.inner(dict(scope, cookies=cookies), receive, send)
           ^^^^^^^^^^^^^^^^^^^^^^^^^^^^^^^^^^^^^^^^^^^^^^^^^^^^^^^^^^^^^
  File "/Users/emmidev/.pyenv/versions/3.11.8/lib/python3.11/site-packages/channels/sessions.py", line 261, in __call__
    return await self.inner(wrapper.scope, receive, wrapper.send)
           ^^^^^^^^^^^^^^^^^^^^^^^^^^^^^^^^^^^^^^^^^^^^^^^^^^^^^^
  File "/Users/emmidev/.pyenv/versions/3.11.8/lib/python3.11/site-packages/channels/auth.py", line 185, in __call__
    return await super().__call__(scope, receive, send)
           ^^^^^^^^^^^^^^^^^^^^^^^^^^^^^^^^^^^^^^^^^^^^
  File "/Users/emmidev/.pyenv/versions/3.11.8/lib/python3.11/site-packages/channels/middleware.py", line 24, in __call__
    return await self.inner(scope, receive, send)
           ^^^^^^^^^^^^^^^^^^^^^^^^^^^^^^^^^^^^^^
  File "/Users/emmidev/.pyenv/versions/3.11.8/lib/python3.11/site-packages/channels/routing.py", line 136, in __call__
    raise ValueError("No route found for path %r." % path)
ValueError: No route found for path 'ws/portfolio/'.
ERROR 2025-10-30 13:34:59,476 server 17195 4574504448 Exception inside application: No route found for path 'ws/portfolio/'.
Traceback (most recent call last):
  File "/Users/emmidev/.pyenv/versions/3.11.8/lib/python3.11/site-packages/channels/routing.py", line 48, in __call__
    return await application(scope, receive, send)
           ^^^^^^^^^^^^^^^^^^^^^^^^^^^^^^^^^^^^^^^
  File "/Users/emmidev/.pyenv/versions/3.11.8/lib/python3.11/site-packages/channels/sessions.py", line 44, in __call__
    return await self.inner(dict(scope, cookies=cookies), receive, send)
           ^^^^^^^^^^^^^^^^^^^^^^^^^^^^^^^^^^^^^^^^^^^^^^^^^^^^^^^^^^^^^
  File "/Users/emmidev/.pyenv/versions/3.11.8/lib/python3.11/site-packages/channels/sessions.py", line 261, in __call__
    return await self.inner(wrapper.scope, receive, wrapper.send)
           ^^^^^^^^^^^^^^^^^^^^^^^^^^^^^^^^^^^^^^^^^^^^^^^^^^^^^^
  File "/Users/emmidev/.pyenv/versions/3.11.8/lib/python3.11/site-packages/channels/auth.py", line 185, in __call__
    return await super().__call__(scope, receive, send)
           ^^^^^^^^^^^^^^^^^^^^^^^^^^^^^^^^^^^^^^^^^^^^
  File "/Users/emmidev/.pyenv/versions/3.11.8/lib/python3.11/site-packages/channels/middleware.py", line 24, in __call__
    return await self.inner(scope, receive, send)
           ^^^^^^^^^^^^^^^^^^^^^^^^^^^^^^^^^^^^^^
  File "/Users/emmidev/.pyenv/versions/3.11.8/lib/python3.11/site-packages/channels/routing.py", line 136, in __call__
    raise ValueError("No route found for path %r." % path)
ValueError: No route found for path 'ws/portfolio/'.
ERROR 2025-10-30 13:35:00,479 server 17195 4574504448 Exception inside application: No route found for path 'ws/portfolio/'.
Traceback (most recent call last):
  File "/Users/emmidev/.pyenv/versions/3.11.8/lib/python3.11/site-packages/channels/routing.py", line 48, in __call__
    return await application(scope, receive, send)
           ^^^^^^^^^^^^^^^^^^^^^^^^^^^^^^^^^^^^^^^
  File "/Users/emmidev/.pyenv/versions/3.11.8/lib/python3.11/site-packages/channels/sessions.py", line 44, in __call__
    return await self.inner(dict(scope, cookies=cookies), receive, send)
           ^^^^^^^^^^^^^^^^^^^^^^^^^^^^^^^^^^^^^^^^^^^^^^^^^^^^^^^^^^^^^
  File "/Users/emmidev/.pyenv/versions/3.11.8/lib/python3.11/site-packages/channels/sessions.py", line 261, in __call__
    return await self.inner(wrapper.scope, receive, wrapper.send)
           ^^^^^^^^^^^^^^^^^^^^^^^^^^^^^^^^^^^^^^^^^^^^^^^^^^^^^^
  File "/Users/emmidev/.pyenv/versions/3.11.8/lib/python3.11/site-packages/channels/auth.py", line 185, in __call__
    return await super().__call__(scope, receive, send)
           ^^^^^^^^^^^^^^^^^^^^^^^^^^^^^^^^^^^^^^^^^^^^
  File "/Users/emmidev/.pyenv/versions/3.11.8/lib/python3.11/site-packages/channels/middleware.py", line 24, in __call__
    return await self.inner(scope, receive, send)
           ^^^^^^^^^^^^^^^^^^^^^^^^^^^^^^^^^^^^^^
  File "/Users/emmidev/.pyenv/versions/3.11.8/lib/python3.11/site-packages/channels/routing.py", line 136, in __call__
    raise ValueError("No route found for path %r." % path)
ValueError: No route found for path 'ws/portfolio/'.
ERROR 2025-10-30 13:35:05,485 server 17195 4574504448 Exception inside application: No route found for path 'ws/portfolio/'.
Traceback (most recent call last):
  File "/Users/emmidev/.pyenv/versions/3.11.8/lib/python3.11/site-packages/channels/routing.py", line 48, in __call__
    return await application(scope, receive, send)
           ^^^^^^^^^^^^^^^^^^^^^^^^^^^^^^^^^^^^^^^
  File "/Users/emmidev/.pyenv/versions/3.11.8/lib/python3.11/site-packages/channels/sessions.py", line 44, in __call__
    return await self.inner(dict(scope, cookies=cookies), receive, send)
           ^^^^^^^^^^^^^^^^^^^^^^^^^^^^^^^^^^^^^^^^^^^^^^^^^^^^^^^^^^^^^
  File "/Users/emmidev/.pyenv/versions/3.11.8/lib/python3.11/site-packages/channels/sessions.py", line 261, in __call__
    return await self.inner(wrapper.scope, receive, wrapper.send)
           ^^^^^^^^^^^^^^^^^^^^^^^^^^^^^^^^^^^^^^^^^^^^^^^^^^^^^^
  File "/Users/emmidev/.pyenv/versions/3.11.8/lib/python3.11/site-packages/channels/auth.py", line 185, in __call__
    return await super().__call__(scope, receive, send)
           ^^^^^^^^^^^^^^^^^^^^^^^^^^^^^^^^^^^^^^^^^^^^
  File "/Users/emmidev/.pyenv/versions/3.11.8/lib/python3.11/site-packages/channels/middleware.py", line 24, in __call__
    return await self.inner(scope, receive, send)
           ^^^^^^^^^^^^^^^^^^^^^^^^^^^^^^^^^^^^^^
  File "/Users/emmidev/.pyenv/versions/3.11.8/lib/python3.11/site-packages/channels/routing.py", line 136, in __call__
    raise ValueError("No route found for path %r." % path)
ValueError: No route found for path 'ws/portfolio/'.
ERROR 2025-10-30 13:35:06,488 server 17195 4574504448 Exception inside application: No route found for path 'ws/portfolio/'.
Traceback (most recent call last):
  File "/Users/emmidev/.pyenv/versions/3.11.8/lib/python3.11/site-packages/channels/routing.py", line 48, in __call__
    return await application(scope, receive, send)
           ^^^^^^^^^^^^^^^^^^^^^^^^^^^^^^^^^^^^^^^
  File "/Users/emmidev/.pyenv/versions/3.11.8/lib/python3.11/site-packages/channels/sessions.py", line 44, in __call__
    return await self.inner(dict(scope, cookies=cookies), receive, send)
           ^^^^^^^^^^^^^^^^^^^^^^^^^^^^^^^^^^^^^^^^^^^^^^^^^^^^^^^^^^^^^
  File "/Users/emmidev/.pyenv/versions/3.11.8/lib/python3.11/site-packages/channels/sessions.py", line 261, in __call__
    return await self.inner(wrapper.scope, receive, wrapper.send)
           ^^^^^^^^^^^^^^^^^^^^^^^^^^^^^^^^^^^^^^^^^^^^^^^^^^^^^^
  File "/Users/emmidev/.pyenv/versions/3.11.8/lib/python3.11/site-packages/channels/auth.py", line 185, in __call__
    return await super().__call__(scope, receive, send)
           ^^^^^^^^^^^^^^^^^^^^^^^^^^^^^^^^^^^^^^^^^^^^
  File "/Users/emmidev/.pyenv/versions/3.11.8/lib/python3.11/site-packages/channels/middleware.py", line 24, in __call__
    return await self.inner(scope, receive, send)
           ^^^^^^^^^^^^^^^^^^^^^^^^^^^^^^^^^^^^^^
  File "/Users/emmidev/.pyenv/versions/3.11.8/lib/python3.11/site-packages/channels/routing.py", line 136, in __call__
    raise ValueError("No route found for path %r." % path)
ValueError: No route found for path 'ws/portfolio/'.
ERROR 2025-10-30 13:35:11,495 server 17195 4574504448 Exception inside application: No route found for path 'ws/portfolio/'.
Traceback (most recent call last):
  File "/Users/emmidev/.pyenv/versions/3.11.8/lib/python3.11/site-packages/channels/routing.py", line 48, in __call__
    return await application(scope, receive, send)
           ^^^^^^^^^^^^^^^^^^^^^^^^^^^^^^^^^^^^^^^
  File "/Users/emmidev/.pyenv/versions/3.11.8/lib/python3.11/site-packages/channels/sessions.py", line 44, in __call__
    return await self.inner(dict(scope, cookies=cookies), receive, send)
           ^^^^^^^^^^^^^^^^^^^^^^^^^^^^^^^^^^^^^^^^^^^^^^^^^^^^^^^^^^^^^
  File "/Users/emmidev/.pyenv/versions/3.11.8/lib/python3.11/site-packages/channels/sessions.py", line 261, in __call__
    return await self.inner(wrapper.scope, receive, wrapper.send)
           ^^^^^^^^^^^^^^^^^^^^^^^^^^^^^^^^^^^^^^^^^^^^^^^^^^^^^^
  File "/Users/emmidev/.pyenv/versions/3.11.8/lib/python3.11/site-packages/channels/auth.py", line 185, in __call__
    return await super().__call__(scope, receive, send)
           ^^^^^^^^^^^^^^^^^^^^^^^^^^^^^^^^^^^^^^^^^^^^
  File "/Users/emmidev/.pyenv/versions/3.11.8/lib/python3.11/site-packages/channels/middleware.py", line 24, in __call__
    return await self.inner(scope, receive, send)
           ^^^^^^^^^^^^^^^^^^^^^^^^^^^^^^^^^^^^^^
  File "/Users/emmidev/.pyenv/versions/3.11.8/lib/python3.11/site-packages/channels/routing.py", line 136, in __call__
    raise ValueError("No route found for path %r." % path)
ValueError: No route found for path 'ws/portfolio/'.
ERROR 2025-10-30 13:35:12,499 server 17195 4574504448 Exception inside application: No route found for path 'ws/portfolio/'.
Traceback (most recent call last):
  File "/Users/emmidev/.pyenv/versions/3.11.8/lib/python3.11/site-packages/channels/routing.py", line 48, in __call__
    return await application(scope, receive, send)
           ^^^^^^^^^^^^^^^^^^^^^^^^^^^^^^^^^^^^^^^
  File "/Users/emmidev/.pyenv/versions/3.11.8/lib/python3.11/site-packages/channels/sessions.py", line 44, in __call__
    return await self.inner(dict(scope, cookies=cookies), receive, send)
           ^^^^^^^^^^^^^^^^^^^^^^^^^^^^^^^^^^^^^^^^^^^^^^^^^^^^^^^^^^^^^
  File "/Users/emmidev/.pyenv/versions/3.11.8/lib/python3.11/site-packages/channels/sessions.py", line 261, in __call__
    return await self.inner(wrapper.scope, receive, wrapper.send)
           ^^^^^^^^^^^^^^^^^^^^^^^^^^^^^^^^^^^^^^^^^^^^^^^^^^^^^^
  File "/Users/emmidev/.pyenv/versions/3.11.8/lib/python3.11/site-packages/channels/auth.py", line 185, in __call__
    return await super().__call__(scope, receive, send)
           ^^^^^^^^^^^^^^^^^^^^^^^^^^^^^^^^^^^^^^^^^^^^
  File "/Users/emmidev/.pyenv/versions/3.11.8/lib/python3.11/site-packages/channels/middleware.py", line 24, in __call__
    return await self.inner(scope, receive, send)
           ^^^^^^^^^^^^^^^^^^^^^^^^^^^^^^^^^^^^^^
  File "/Users/emmidev/.pyenv/versions/3.11.8/lib/python3.11/site-packages/channels/routing.py", line 136, in __call__
    raise ValueError("No route found for path %r." % path)
ValueError: No route found for path 'ws/portfolio/'.
ERROR 2025-10-30 13:35:18,506 server 17195 4574504448 Exception inside application: No route found for path 'ws/portfolio/'.
Traceback (most recent call last):
  File "/Users/emmidev/.pyenv/versions/3.11.8/lib/python3.11/site-packages/channels/routing.py", line 48, in __call__
    return await application(scope, receive, send)
           ^^^^^^^^^^^^^^^^^^^^^^^^^^^^^^^^^^^^^^^
  File "/Users/emmidev/.pyenv/versions/3.11.8/lib/python3.11/site-packages/channels/sessions.py", line 44, in __call__
    return await self.inner(dict(scope, cookies=cookies), receive, send)
           ^^^^^^^^^^^^^^^^^^^^^^^^^^^^^^^^^^^^^^^^^^^^^^^^^^^^^^^^^^^^^
  File "/Users/emmidev/.pyenv/versions/3.11.8/lib/python3.11/site-packages/channels/sessions.py", line 261, in __call__
    return await self.inner(wrapper.scope, receive, wrapper.send)
           ^^^^^^^^^^^^^^^^^^^^^^^^^^^^^^^^^^^^^^^^^^^^^^^^^^^^^^
  File "/Users/emmidev/.pyenv/versions/3.11.8/lib/python3.11/site-packages/channels/auth.py", line 185, in __call__
    return await super().__call__(scope, receive, send)
           ^^^^^^^^^^^^^^^^^^^^^^^^^^^^^^^^^^^^^^^^^^^^
  File "/Users/emmidev/.pyenv/versions/3.11.8/lib/python3.11/site-packages/channels/middleware.py", line 24, in __call__
    return await self.inner(scope, receive, send)
           ^^^^^^^^^^^^^^^^^^^^^^^^^^^^^^^^^^^^^^
  File "/Users/emmidev/.pyenv/versions/3.11.8/lib/python3.11/site-packages/channels/routing.py", line 136, in __call__
    raise ValueError("No route found for path %r." % path)
ValueError: No route found for path 'ws/portfolio/'.
ERROR 2025-10-30 13:35:21,511 server 17195 4574504448 Exception inside application: No route found for path 'ws/portfolio/'.
Traceback (most recent call last):
  File "/Users/emmidev/.pyenv/versions/3.11.8/lib/python3.11/site-packages/channels/routing.py", line 48, in __call__
    return await application(scope, receive, send)
           ^^^^^^^^^^^^^^^^^^^^^^^^^^^^^^^^^^^^^^^
  File "/Users/emmidev/.pyenv/versions/3.11.8/lib/python3.11/site-packages/channels/sessions.py", line 44, in __call__
    return await self.inner(dict(scope, cookies=cookies), receive, send)
           ^^^^^^^^^^^^^^^^^^^^^^^^^^^^^^^^^^^^^^^^^^^^^^^^^^^^^^^^^^^^^
  File "/Users/emmidev/.pyenv/versions/3.11.8/lib/python3.11/site-packages/channels/sessions.py", line 261, in __call__
    return await self.inner(wrapper.scope, receive, wrapper.send)
           ^^^^^^^^^^^^^^^^^^^^^^^^^^^^^^^^^^^^^^^^^^^^^^^^^^^^^^
  File "/Users/emmidev/.pyenv/versions/3.11.8/lib/python3.11/site-packages/channels/auth.py", line 185, in __call__
    return await super().__call__(scope, receive, send)
           ^^^^^^^^^^^^^^^^^^^^^^^^^^^^^^^^^^^^^^^^^^^^
  File "/Users/emmidev/.pyenv/versions/3.11.8/lib/python3.11/site-packages/channels/middleware.py", line 24, in __call__
    return await self.inner(scope, receive, send)
           ^^^^^^^^^^^^^^^^^^^^^^^^^^^^^^^^^^^^^^
  File "/Users/emmidev/.pyenv/versions/3.11.8/lib/python3.11/site-packages/channels/routing.py", line 136, in __call__
    raise ValueError("No route found for path %r." % path)
ValueError: No route found for path 'ws/portfolio/'.
ERROR 2025-10-30 13:35:26,520 server 17195 4574504448 Exception inside application: No route found for path 'ws/portfolio/'.
Traceback (most recent call last):
  File "/Users/emmidev/.pyenv/versions/3.11.8/lib/python3.11/site-packages/channels/routing.py", line 48, in __call__
    return await application(scope, receive, send)
           ^^^^^^^^^^^^^^^^^^^^^^^^^^^^^^^^^^^^^^^
  File "/Users/emmidev/.pyenv/versions/3.11.8/lib/python3.11/site-packages/channels/sessions.py", line 44, in __call__
    return await self.inner(dict(scope, cookies=cookies), receive, send)
           ^^^^^^^^^^^^^^^^^^^^^^^^^^^^^^^^^^^^^^^^^^^^^^^^^^^^^^^^^^^^^
  File "/Users/emmidev/.pyenv/versions/3.11.8/lib/python3.11/site-packages/channels/sessions.py", line 261, in __call__
    return await self.inner(wrapper.scope, receive, wrapper.send)
           ^^^^^^^^^^^^^^^^^^^^^^^^^^^^^^^^^^^^^^^^^^^^^^^^^^^^^^
  File "/Users/emmidev/.pyenv/versions/3.11.8/lib/python3.11/site-packages/channels/auth.py", line 185, in __call__
    return await super().__call__(scope, receive, send)
           ^^^^^^^^^^^^^^^^^^^^^^^^^^^^^^^^^^^^^^^^^^^^
  File "/Users/emmidev/.pyenv/versions/3.11.8/lib/python3.11/site-packages/channels/middleware.py", line 24, in __call__
    return await self.inner(scope, receive, send)
           ^^^^^^^^^^^^^^^^^^^^^^^^^^^^^^^^^^^^^^
  File "/Users/emmidev/.pyenv/versions/3.11.8/lib/python3.11/site-packages/channels/routing.py", line 136, in __call__
    raise ValueError("No route found for path %r." % path)
ValueError: No route found for path 'ws/portfolio/'.
ERROR 2025-10-30 13:35:28,525 server 17195 4574504448 Exception inside application: No route found for path 'ws/portfolio/'.
Traceback (most recent call last):
  File "/Users/emmidev/.pyenv/versions/3.11.8/lib/python3.11/site-packages/channels/routing.py", line 48, in __call__
    return await application(scope, receive, send)
           ^^^^^^^^^^^^^^^^^^^^^^^^^^^^^^^^^^^^^^^
  File "/Users/emmidev/.pyenv/versions/3.11.8/lib/python3.11/site-packages/channels/sessions.py", line 44, in __call__
    return await self.inner(dict(scope, cookies=cookies), receive, send)
           ^^^^^^^^^^^^^^^^^^^^^^^^^^^^^^^^^^^^^^^^^^^^^^^^^^^^^^^^^^^^^
  File "/Users/emmidev/.pyenv/versions/3.11.8/lib/python3.11/site-packages/channels/sessions.py", line 261, in __call__
    return await self.inner(wrapper.scope, receive, wrapper.send)
           ^^^^^^^^^^^^^^^^^^^^^^^^^^^^^^^^^^^^^^^^^^^^^^^^^^^^^^
  File "/Users/emmidev/.pyenv/versions/3.11.8/lib/python3.11/site-packages/channels/auth.py", line 185, in __call__
    return await super().__call__(scope, receive, send)
           ^^^^^^^^^^^^^^^^^^^^^^^^^^^^^^^^^^^^^^^^^^^^
  File "/Users/emmidev/.pyenv/versions/3.11.8/lib/python3.11/site-packages/channels/middleware.py", line 24, in __call__
    return await self.inner(scope, receive, send)
           ^^^^^^^^^^^^^^^^^^^^^^^^^^^^^^^^^^^^^^
  File "/Users/emmidev/.pyenv/versions/3.11.8/lib/python3.11/site-packages/channels/routing.py", line 136, in __call__
    raise ValueError("No route found for path %r." % path)
ValueError: No route found for path 'ws/portfolio/'.
ERROR 2025-10-30 13:35:36,533 server 17195 4574504448 Exception inside application: No route found for path 'ws/portfolio/'.
Traceback (most recent call last):
  File "/Users/emmidev/.pyenv/versions/3.11.8/lib/python3.11/site-packages/channels/routing.py", line 48, in __call__
    return await application(scope, receive, send)
           ^^^^^^^^^^^^^^^^^^^^^^^^^^^^^^^^^^^^^^^
  File "/Users/emmidev/.pyenv/versions/3.11.8/lib/python3.11/site-packages/channels/sessions.py", line 44, in __call__
    return await self.inner(dict(scope, cookies=cookies), receive, send)
           ^^^^^^^^^^^^^^^^^^^^^^^^^^^^^^^^^^^^^^^^^^^^^^^^^^^^^^^^^^^^^
  File "/Users/emmidev/.pyenv/versions/3.11.8/lib/python3.11/site-packages/channels/sessions.py", line 261, in __call__
    return await self.inner(wrapper.scope, receive, wrapper.send)
           ^^^^^^^^^^^^^^^^^^^^^^^^^^^^^^^^^^^^^^^^^^^^^^^^^^^^^^
  File "/Users/emmidev/.pyenv/versions/3.11.8/lib/python3.11/site-packages/channels/auth.py", line 185, in __call__
    return await super().__call__(scope, receive, send)
           ^^^^^^^^^^^^^^^^^^^^^^^^^^^^^^^^^^^^^^^^^^^^
  File "/Users/emmidev/.pyenv/versions/3.11.8/lib/python3.11/site-packages/channels/middleware.py", line 24, in __call__
    return await self.inner(scope, receive, send)
           ^^^^^^^^^^^^^^^^^^^^^^^^^^^^^^^^^^^^^^
  File "/Users/emmidev/.pyenv/versions/3.11.8/lib/python3.11/site-packages/channels/routing.py", line 136, in __call__
    raise ValueError("No route found for path %r." % path)
ValueError: No route found for path 'ws/portfolio/'.
ERROR 2025-10-30 13:35:38,538 server 17195 4574504448 Exception inside application: No route found for path 'ws/portfolio/'.
Traceback (most recent call last):
  File "/Users/emmidev/.pyenv/versions/3.11.8/lib/python3.11/site-packages/channels/routing.py", line 48, in __call__
    return await application(scope, receive, send)
           ^^^^^^^^^^^^^^^^^^^^^^^^^^^^^^^^^^^^^^^
  File "/Users/emmidev/.pyenv/versions/3.11.8/lib/python3.11/site-packages/channels/sessions.py", line 44, in __call__
    return await self.inner(dict(scope, cookies=cookies), receive, send)
           ^^^^^^^^^^^^^^^^^^^^^^^^^^^^^^^^^^^^^^^^^^^^^^^^^^^^^^^^^^^^^
  File "/Users/emmidev/.pyenv/versions/3.11.8/lib/python3.11/site-packages/channels/sessions.py", line 261, in __call__
    return await self.inner(wrapper.scope, receive, wrapper.send)
           ^^^^^^^^^^^^^^^^^^^^^^^^^^^^^^^^^^^^^^^^^^^^^^^^^^^^^^
  File "/Users/emmidev/.pyenv/versions/3.11.8/lib/python3.11/site-packages/channels/auth.py", line 185, in __call__
    return await super().__call__(scope, receive, send)
           ^^^^^^^^^^^^^^^^^^^^^^^^^^^^^^^^^^^^^^^^^^^^
  File "/Users/emmidev/.pyenv/versions/3.11.8/lib/python3.11/site-packages/channels/middleware.py", line 24, in __call__
    return await self.inner(scope, receive, send)
           ^^^^^^^^^^^^^^^^^^^^^^^^^^^^^^^^^^^^^^
  File "/Users/emmidev/.pyenv/versions/3.11.8/lib/python3.11/site-packages/channels/routing.py", line 136, in __call__
    raise ValueError("No route found for path %r." % path)
ValueError: No route found for path 'ws/portfolio/'.
ERROR 2025-10-30 13:35:43,544 server 17195 4574504448 Exception inside application: No route found for path 'ws/portfolio/'.
Traceback (most recent call last):
  File "/Users/emmidev/.pyenv/versions/3.11.8/lib/python3.11/site-packages/channels/routing.py", line 48, in __call__
    return await application(scope, receive, send)
           ^^^^^^^^^^^^^^^^^^^^^^^^^^^^^^^^^^^^^^^
  File "/Users/emmidev/.pyenv/versions/3.11.8/lib/python3.11/site-packages/channels/sessions.py", line 44, in __call__
    return await self.inner(dict(scope, cookies=cookies), receive, send)
           ^^^^^^^^^^^^^^^^^^^^^^^^^^^^^^^^^^^^^^^^^^^^^^^^^^^^^^^^^^^^^
  File "/Users/emmidev/.pyenv/versions/3.11.8/lib/python3.11/site-packages/channels/sessions.py", line 261, in __call__
    return await self.inner(wrapper.scope, receive, wrapper.send)
           ^^^^^^^^^^^^^^^^^^^^^^^^^^^^^^^^^^^^^^^^^^^^^^^^^^^^^^
  File "/Users/emmidev/.pyenv/versions/3.11.8/lib/python3.11/site-packages/channels/auth.py", line 185, in __call__
    return await super().__call__(scope, receive, send)
           ^^^^^^^^^^^^^^^^^^^^^^^^^^^^^^^^^^^^^^^^^^^^
  File "/Users/emmidev/.pyenv/versions/3.11.8/lib/python3.11/site-packages/channels/middleware.py", line 24, in __call__
    return await self.inner(scope, receive, send)
           ^^^^^^^^^^^^^^^^^^^^^^^^^^^^^^^^^^^^^^
  File "/Users/emmidev/.pyenv/versions/3.11.8/lib/python3.11/site-packages/channels/routing.py", line 136, in __call__
    raise ValueError("No route found for path %r." % path)
ValueError: No route found for path 'ws/portfolio/'.
ERROR 2025-10-30 13:35:47,552 server 17195 4574504448 Exception inside application: No route found for path 'ws/portfolio/'.
Traceback (most recent call last):
  File "/Users/emmidev/.pyenv/versions/3.11.8/lib/python3.11/site-packages/channels/routing.py", line 48, in __call__
    return await application(scope, receive, send)
           ^^^^^^^^^^^^^^^^^^^^^^^^^^^^^^^^^^^^^^^
  File "/Users/emmidev/.pyenv/versions/3.11.8/lib/python3.11/site-packages/channels/sessions.py", line 44, in __call__
    return await self.inner(dict(scope, cookies=cookies), receive, send)
           ^^^^^^^^^^^^^^^^^^^^^^^^^^^^^^^^^^^^^^^^^^^^^^^^^^^^^^^^^^^^^
  File "/Users/emmidev/.pyenv/versions/3.11.8/lib/python3.11/site-packages/channels/sessions.py", line 261, in __call__
    return await self.inner(wrapper.scope, receive, wrapper.send)
           ^^^^^^^^^^^^^^^^^^^^^^^^^^^^^^^^^^^^^^^^^^^^^^^^^^^^^^
  File "/Users/emmidev/.pyenv/versions/3.11.8/lib/python3.11/site-packages/channels/auth.py", line 185, in __call__
    return await super().__call__(scope, receive, send)
           ^^^^^^^^^^^^^^^^^^^^^^^^^^^^^^^^^^^^^^^^^^^^
  File "/Users/emmidev/.pyenv/versions/3.11.8/lib/python3.11/site-packages/channels/middleware.py", line 24, in __call__
    return await self.inner(scope, receive, send)
           ^^^^^^^^^^^^^^^^^^^^^^^^^^^^^^^^^^^^^^
  File "/Users/emmidev/.pyenv/versions/3.11.8/lib/python3.11/site-packages/channels/routing.py", line 136, in __call__
    raise ValueError("No route found for path %r." % path)
ValueError: No route found for path 'ws/portfolio/'.
ERROR 2025-10-30 13:35:53,559 server 17195 4574504448 Exception inside application: No route found for path 'ws/portfolio/'.
Traceback (most recent call last):
  File "/Users/emmidev/.pyenv/versions/3.11.8/lib/python3.11/site-packages/channels/routing.py", line 48, in __call__
    return await application(scope, receive, send)
           ^^^^^^^^^^^^^^^^^^^^^^^^^^^^^^^^^^^^^^^
  File "/Users/emmidev/.pyenv/versions/3.11.8/lib/python3.11/site-packages/channels/sessions.py", line 44, in __call__
    return await self.inner(dict(scope, cookies=cookies), receive, send)
           ^^^^^^^^^^^^^^^^^^^^^^^^^^^^^^^^^^^^^^^^^^^^^^^^^^^^^^^^^^^^^
  File "/Users/emmidev/.pyenv/versions/3.11.8/lib/python3.11/site-packages/channels/sessions.py", line 261, in __call__
    return await self.inner(wrapper.scope, receive, wrapper.send)
           ^^^^^^^^^^^^^^^^^^^^^^^^^^^^^^^^^^^^^^^^^^^^^^^^^^^^^^
  File "/Users/emmidev/.pyenv/versions/3.11.8/lib/python3.11/site-packages/channels/auth.py", line 185, in __call__
    return await super().__call__(scope, receive, send)
           ^^^^^^^^^^^^^^^^^^^^^^^^^^^^^^^^^^^^^^^^^^^^
  File "/Users/emmidev/.pyenv/versions/3.11.8/lib/python3.11/site-packages/channels/middleware.py", line 24, in __call__
    return await self.inner(scope, receive, send)
           ^^^^^^^^^^^^^^^^^^^^^^^^^^^^^^^^^^^^^^
  File "/Users/emmidev/.pyenv/versions/3.11.8/lib/python3.11/site-packages/channels/routing.py", line 136, in __call__
    raise ValueError("No route found for path %r." % path)
ValueError: No route found for path 'ws/portfolio/'.
ERROR 2025-10-30 13:35:55,562 server 17195 4574504448 Exception inside application: No route found for path 'ws/portfolio/'.
Traceback (most recent call last):
  File "/Users/emmidev/.pyenv/versions/3.11.8/lib/python3.11/site-packages/channels/routing.py", line 48, in __call__
    return await application(scope, receive, send)
           ^^^^^^^^^^^^^^^^^^^^^^^^^^^^^^^^^^^^^^^
  File "/Users/emmidev/.pyenv/versions/3.11.8/lib/python3.11/site-packages/channels/sessions.py", line 44, in __call__
    return await self.inner(dict(scope, cookies=cookies), receive, send)
           ^^^^^^^^^^^^^^^^^^^^^^^^^^^^^^^^^^^^^^^^^^^^^^^^^^^^^^^^^^^^^
  File "/Users/emmidev/.pyenv/versions/3.11.8/lib/python3.11/site-packages/channels/sessions.py", line 261, in __call__
    return await self.inner(wrapper.scope, receive, wrapper.send)
           ^^^^^^^^^^^^^^^^^^^^^^^^^^^^^^^^^^^^^^^^^^^^^^^^^^^^^^
  File "/Users/emmidev/.pyenv/versions/3.11.8/lib/python3.11/site-packages/channels/auth.py", line 185, in __call__
    return await super().__call__(scope, receive, send)
           ^^^^^^^^^^^^^^^^^^^^^^^^^^^^^^^^^^^^^^^^^^^^
  File "/Users/emmidev/.pyenv/versions/3.11.8/lib/python3.11/site-packages/channels/middleware.py", line 24, in __call__
    return await self.inner(scope, receive, send)
           ^^^^^^^^^^^^^^^^^^^^^^^^^^^^^^^^^^^^^^
  File "/Users/emmidev/.pyenv/versions/3.11.8/lib/python3.11/site-packages/channels/routing.py", line 136, in __call__
    raise ValueError("No route found for path %r." % path)
ValueError: No route found for path 'ws/portfolio/'.
ERROR 2025-10-30 13:36:02,573 server 17195 4574504448 Exception inside application: No route found for path 'ws/portfolio/'.
Traceback (most recent call last):
  File "/Users/emmidev/.pyenv/versions/3.11.8/lib/python3.11/site-packages/channels/routing.py", line 48, in __call__
    return await application(scope, receive, send)
           ^^^^^^^^^^^^^^^^^^^^^^^^^^^^^^^^^^^^^^^
  File "/Users/emmidev/.pyenv/versions/3.11.8/lib/python3.11/site-packages/channels/sessions.py", line 44, in __call__
    return await self.inner(dict(scope, cookies=cookies), receive, send)
           ^^^^^^^^^^^^^^^^^^^^^^^^^^^^^^^^^^^^^^^^^^^^^^^^^^^^^^^^^^^^^
  File "/Users/emmidev/.pyenv/versions/3.11.8/lib/python3.11/site-packages/channels/sessions.py", line 261, in __call__
    return await self.inner(wrapper.scope, receive, wrapper.send)
           ^^^^^^^^^^^^^^^^^^^^^^^^^^^^^^^^^^^^^^^^^^^^^^^^^^^^^^
  File "/Users/emmidev/.pyenv/versions/3.11.8/lib/python3.11/site-packages/channels/auth.py", line 185, in __call__
    return await super().__call__(scope, receive, send)
           ^^^^^^^^^^^^^^^^^^^^^^^^^^^^^^^^^^^^^^^^^^^^
  File "/Users/emmidev/.pyenv/versions/3.11.8/lib/python3.11/site-packages/channels/middleware.py", line 24, in __call__
    return await self.inner(scope, receive, send)
           ^^^^^^^^^^^^^^^^^^^^^^^^^^^^^^^^^^^^^^
  File "/Users/emmidev/.pyenv/versions/3.11.8/lib/python3.11/site-packages/channels/routing.py", line 136, in __call__
    raise ValueError("No route found for path %r." % path)
ValueError: No route found for path 'ws/portfolio/'.
ERROR 2025-10-30 13:36:03,576 server 17195 4574504448 Exception inside application: No route found for path 'ws/portfolio/'.
Traceback (most recent call last):
  File "/Users/emmidev/.pyenv/versions/3.11.8/lib/python3.11/site-packages/channels/routing.py", line 48, in __call__
    return await application(scope, receive, send)
           ^^^^^^^^^^^^^^^^^^^^^^^^^^^^^^^^^^^^^^^
  File "/Users/emmidev/.pyenv/versions/3.11.8/lib/python3.11/site-packages/channels/sessions.py", line 44, in __call__
    return await self.inner(dict(scope, cookies=cookies), receive, send)
           ^^^^^^^^^^^^^^^^^^^^^^^^^^^^^^^^^^^^^^^^^^^^^^^^^^^^^^^^^^^^^
  File "/Users/emmidev/.pyenv/versions/3.11.8/lib/python3.11/site-packages/channels/sessions.py", line 261, in __call__
    return await self.inner(wrapper.scope, receive, wrapper.send)
           ^^^^^^^^^^^^^^^^^^^^^^^^^^^^^^^^^^^^^^^^^^^^^^^^^^^^^^
  File "/Users/emmidev/.pyenv/versions/3.11.8/lib/python3.11/site-packages/channels/auth.py", line 185, in __call__
    return await super().__call__(scope, receive, send)
           ^^^^^^^^^^^^^^^^^^^^^^^^^^^^^^^^^^^^^^^^^^^^
  File "/Users/emmidev/.pyenv/versions/3.11.8/lib/python3.11/site-packages/channels/middleware.py", line 24, in __call__
    return await self.inner(scope, receive, send)
           ^^^^^^^^^^^^^^^^^^^^^^^^^^^^^^^^^^^^^^
  File "/Users/emmidev/.pyenv/versions/3.11.8/lib/python3.11/site-packages/channels/routing.py", line 136, in __call__
    raise ValueError("No route found for path %r." % path)
ValueError: No route found for path 'ws/portfolio/'.
ERROR 2025-10-30 13:36:11,583 server 17195 4574504448 Exception inside application: No route found for path 'ws/portfolio/'.
Traceback (most recent call last):
  File "/Users/emmidev/.pyenv/versions/3.11.8/lib/python3.11/site-packages/channels/routing.py", line 48, in __call__
    return await application(scope, receive, send)
           ^^^^^^^^^^^^^^^^^^^^^^^^^^^^^^^^^^^^^^^
  File "/Users/emmidev/.pyenv/versions/3.11.8/lib/python3.11/site-packages/channels/sessions.py", line 44, in __call__
    return await self.inner(dict(scope, cookies=cookies), receive, send)
           ^^^^^^^^^^^^^^^^^^^^^^^^^^^^^^^^^^^^^^^^^^^^^^^^^^^^^^^^^^^^^
  File "/Users/emmidev/.pyenv/versions/3.11.8/lib/python3.11/site-packages/channels/sessions.py", line 261, in __call__
    return await self.inner(wrapper.scope, receive, wrapper.send)
           ^^^^^^^^^^^^^^^^^^^^^^^^^^^^^^^^^^^^^^^^^^^^^^^^^^^^^^
  File "/Users/emmidev/.pyenv/versions/3.11.8/lib/python3.11/site-packages/channels/auth.py", line 185, in __call__
    return await super().__call__(scope, receive, send)
           ^^^^^^^^^^^^^^^^^^^^^^^^^^^^^^^^^^^^^^^^^^^^
  File "/Users/emmidev/.pyenv/versions/3.11.8/lib/python3.11/site-packages/channels/middleware.py", line 24, in __call__
    return await self.inner(scope, receive, send)
           ^^^^^^^^^^^^^^^^^^^^^^^^^^^^^^^^^^^^^^
  File "/Users/emmidev/.pyenv/versions/3.11.8/lib/python3.11/site-packages/channels/routing.py", line 136, in __call__
    raise ValueError("No route found for path %r." % path)
ValueError: No route found for path 'ws/portfolio/'.
ERROR 2025-10-30 13:36:12,586 server 17195 4574504448 Exception inside application: No route found for path 'ws/portfolio/'.
Traceback (most recent call last):
  File "/Users/emmidev/.pyenv/versions/3.11.8/lib/python3.11/site-packages/channels/routing.py", line 48, in __call__
    return await application(scope, receive, send)
           ^^^^^^^^^^^^^^^^^^^^^^^^^^^^^^^^^^^^^^^
  File "/Users/emmidev/.pyenv/versions/3.11.8/lib/python3.11/site-packages/channels/sessions.py", line 44, in __call__
    return await self.inner(dict(scope, cookies=cookies), receive, send)
           ^^^^^^^^^^^^^^^^^^^^^^^^^^^^^^^^^^^^^^^^^^^^^^^^^^^^^^^^^^^^^
  File "/Users/emmidev/.pyenv/versions/3.11.8/lib/python3.11/site-packages/channels/sessions.py", line 261, in __call__
    return await self.inner(wrapper.scope, receive, wrapper.send)
           ^^^^^^^^^^^^^^^^^^^^^^^^^^^^^^^^^^^^^^^^^^^^^^^^^^^^^^
  File "/Users/emmidev/.pyenv/versions/3.11.8/lib/python3.11/site-packages/channels/auth.py", line 185, in __call__
    return await super().__call__(scope, receive, send)
           ^^^^^^^^^^^^^^^^^^^^^^^^^^^^^^^^^^^^^^^^^^^^
  File "/Users/emmidev/.pyenv/versions/3.11.8/lib/python3.11/site-packages/channels/middleware.py", line 24, in __call__
    return await self.inner(scope, receive, send)
           ^^^^^^^^^^^^^^^^^^^^^^^^^^^^^^^^^^^^^^
  File "/Users/emmidev/.pyenv/versions/3.11.8/lib/python3.11/site-packages/channels/routing.py", line 136, in __call__
    raise ValueError("No route found for path %r." % path)
ValueError: No route found for path 'ws/portfolio/'.
ERROR 2025-10-30 13:36:21,598 server 17195 4574504448 Exception inside application: No route found for path 'ws/portfolio/'.
Traceback (most recent call last):
  File "/Users/emmidev/.pyenv/versions/3.11.8/lib/python3.11/site-packages/channels/routing.py", line 48, in __call__
    return await application(scope, receive, send)
           ^^^^^^^^^^^^^^^^^^^^^^^^^^^^^^^^^^^^^^^
  File "/Users/emmidev/.pyenv/versions/3.11.8/lib/python3.11/site-packages/channels/sessions.py", line 44, in __call__
    return await self.inner(dict(scope, cookies=cookies), receive, send)
           ^^^^^^^^^^^^^^^^^^^^^^^^^^^^^^^^^^^^^^^^^^^^^^^^^^^^^^^^^^^^^
  File "/Users/emmidev/.pyenv/versions/3.11.8/lib/python3.11/site-packages/channels/sessions.py", line 261, in __call__
    return await self.inner(wrapper.scope, receive, wrapper.send)
           ^^^^^^^^^^^^^^^^^^^^^^^^^^^^^^^^^^^^^^^^^^^^^^^^^^^^^^
  File "/Users/emmidev/.pyenv/versions/3.11.8/lib/python3.11/site-packages/channels/auth.py", line 185, in __call__
    return await super().__call__(scope, receive, send)
           ^^^^^^^^^^^^^^^^^^^^^^^^^^^^^^^^^^^^^^^^^^^^
  File "/Users/emmidev/.pyenv/versions/3.11.8/lib/python3.11/site-packages/channels/middleware.py", line 24, in __call__
    return await self.inner(scope, receive, send)
           ^^^^^^^^^^^^^^^^^^^^^^^^^^^^^^^^^^^^^^
  File "/Users/emmidev/.pyenv/versions/3.11.8/lib/python3.11/site-packages/channels/routing.py", line 136, in __call__
    raise ValueError("No route found for path %r." % path)
ValueError: No route found for path 'ws/portfolio/'.
ERROR 2025-10-30 13:36:22,601 server 17195 4574504448 Exception inside application: No route found for path 'ws/portfolio/'.
Traceback (most recent call last):
  File "/Users/emmidev/.pyenv/versions/3.11.8/lib/python3.11/site-packages/channels/routing.py", line 48, in __call__
    return await application(scope, receive, send)
           ^^^^^^^^^^^^^^^^^^^^^^^^^^^^^^^^^^^^^^^
  File "/Users/emmidev/.pyenv/versions/3.11.8/lib/python3.11/site-packages/channels/sessions.py", line 44, in __call__
    return await self.inner(dict(scope, cookies=cookies), receive, send)
           ^^^^^^^^^^^^^^^^^^^^^^^^^^^^^^^^^^^^^^^^^^^^^^^^^^^^^^^^^^^^^
  File "/Users/emmidev/.pyenv/versions/3.11.8/lib/python3.11/site-packages/channels/sessions.py", line 261, in __call__
    return await self.inner(wrapper.scope, receive, wrapper.send)
           ^^^^^^^^^^^^^^^^^^^^^^^^^^^^^^^^^^^^^^^^^^^^^^^^^^^^^^
  File "/Users/emmidev/.pyenv/versions/3.11.8/lib/python3.11/site-packages/channels/auth.py", line 185, in __call__
    return await super().__call__(scope, receive, send)
           ^^^^^^^^^^^^^^^^^^^^^^^^^^^^^^^^^^^^^^^^^^^^
  File "/Users/emmidev/.pyenv/versions/3.11.8/lib/python3.11/site-packages/channels/middleware.py", line 24, in __call__
    return await self.inner(scope, receive, send)
           ^^^^^^^^^^^^^^^^^^^^^^^^^^^^^^^^^^^^^^
  File "/Users/emmidev/.pyenv/versions/3.11.8/lib/python3.11/site-packages/channels/routing.py", line 136, in __call__
    raise ValueError("No route found for path %r." % path)
ValueError: No route found for path 'ws/portfolio/'.
ERROR 2025-10-30 13:36:28,608 server 17195 4574504448 Exception inside application: No route found for path 'ws/portfolio/'.
Traceback (most recent call last):
  File "/Users/emmidev/.pyenv/versions/3.11.8/lib/python3.11/site-packages/channels/routing.py", line 48, in __call__
    return await application(scope, receive, send)
           ^^^^^^^^^^^^^^^^^^^^^^^^^^^^^^^^^^^^^^^
  File "/Users/emmidev/.pyenv/versions/3.11.8/lib/python3.11/site-packages/channels/sessions.py", line 44, in __call__
    return await self.inner(dict(scope, cookies=cookies), receive, send)
           ^^^^^^^^^^^^^^^^^^^^^^^^^^^^^^^^^^^^^^^^^^^^^^^^^^^^^^^^^^^^^
  File "/Users/emmidev/.pyenv/versions/3.11.8/lib/python3.11/site-packages/channels/sessions.py", line 261, in __call__
    return await self.inner(wrapper.scope, receive, wrapper.send)
           ^^^^^^^^^^^^^^^^^^^^^^^^^^^^^^^^^^^^^^^^^^^^^^^^^^^^^^
  File "/Users/emmidev/.pyenv/versions/3.11.8/lib/python3.11/site-packages/channels/auth.py", line 185, in __call__
    return await super().__call__(scope, receive, send)
           ^^^^^^^^^^^^^^^^^^^^^^^^^^^^^^^^^^^^^^^^^^^^
  File "/Users/emmidev/.pyenv/versions/3.11.8/lib/python3.11/site-packages/channels/middleware.py", line 24, in __call__
    return await self.inner(scope, receive, send)
           ^^^^^^^^^^^^^^^^^^^^^^^^^^^^^^^^^^^^^^
  File "/Users/emmidev/.pyenv/versions/3.11.8/lib/python3.11/site-packages/channels/routing.py", line 136, in __call__
    raise ValueError("No route found for path %r." % path)
ValueError: No route found for path 'ws/portfolio/'.
ERROR 2025-10-30 13:36:32,616 server 17195 4574504448 Exception inside application: No route found for path 'ws/portfolio/'.
Traceback (most recent call last):
  File "/Users/emmidev/.pyenv/versions/3.11.8/lib/python3.11/site-packages/channels/routing.py", line 48, in __call__
    return await application(scope, receive, send)
           ^^^^^^^^^^^^^^^^^^^^^^^^^^^^^^^^^^^^^^^
  File "/Users/emmidev/.pyenv/versions/3.11.8/lib/python3.11/site-packages/channels/sessions.py", line 44, in __call__
    return await self.inner(dict(scope, cookies=cookies), receive, send)
           ^^^^^^^^^^^^^^^^^^^^^^^^^^^^^^^^^^^^^^^^^^^^^^^^^^^^^^^^^^^^^
  File "/Users/emmidev/.pyenv/versions/3.11.8/lib/python3.11/site-packages/channels/sessions.py", line 261, in __call__
    return await self.inner(wrapper.scope, receive, wrapper.send)
           ^^^^^^^^^^^^^^^^^^^^^^^^^^^^^^^^^^^^^^^^^^^^^^^^^^^^^^
  File "/Users/emmidev/.pyenv/versions/3.11.8/lib/python3.11/site-packages/channels/auth.py", line 185, in __call__
    return await super().__call__(scope, receive, send)
           ^^^^^^^^^^^^^^^^^^^^^^^^^^^^^^^^^^^^^^^^^^^^
  File "/Users/emmidev/.pyenv/versions/3.11.8/lib/python3.11/site-packages/channels/middleware.py", line 24, in __call__
    return await self.inner(scope, receive, send)
           ^^^^^^^^^^^^^^^^^^^^^^^^^^^^^^^^^^^^^^
  File "/Users/emmidev/.pyenv/versions/3.11.8/lib/python3.11/site-packages/channels/routing.py", line 136, in __call__
    raise ValueError("No route found for path %r." % path)
ValueError: No route found for path 'ws/portfolio/'.
ERROR 2025-10-30 13:36:38,623 server 17195 4574504448 Exception inside application: No route found for path 'ws/portfolio/'.
Traceback (most recent call last):
  File "/Users/emmidev/.pyenv/versions/3.11.8/lib/python3.11/site-packages/channels/routing.py", line 48, in __call__
    return await application(scope, receive, send)
           ^^^^^^^^^^^^^^^^^^^^^^^^^^^^^^^^^^^^^^^
  File "/Users/emmidev/.pyenv/versions/3.11.8/lib/python3.11/site-packages/channels/sessions.py", line 44, in __call__
    return await self.inner(dict(scope, cookies=cookies), receive, send)
           ^^^^^^^^^^^^^^^^^^^^^^^^^^^^^^^^^^^^^^^^^^^^^^^^^^^^^^^^^^^^^
  File "/Users/emmidev/.pyenv/versions/3.11.8/lib/python3.11/site-packages/channels/sessions.py", line 261, in __call__
    return await self.inner(wrapper.scope, receive, wrapper.send)
           ^^^^^^^^^^^^^^^^^^^^^^^^^^^^^^^^^^^^^^^^^^^^^^^^^^^^^^
  File "/Users/emmidev/.pyenv/versions/3.11.8/lib/python3.11/site-packages/channels/auth.py", line 185, in __call__
    return await super().__call__(scope, receive, send)
           ^^^^^^^^^^^^^^^^^^^^^^^^^^^^^^^^^^^^^^^^^^^^
  File "/Users/emmidev/.pyenv/versions/3.11.8/lib/python3.11/site-packages/channels/middleware.py", line 24, in __call__
    return await self.inner(scope, receive, send)
           ^^^^^^^^^^^^^^^^^^^^^^^^^^^^^^^^^^^^^^
  File "/Users/emmidev/.pyenv/versions/3.11.8/lib/python3.11/site-packages/channels/routing.py", line 136, in __call__
    raise ValueError("No route found for path %r." % path)
ValueError: No route found for path 'ws/portfolio/'.
ERROR 2025-10-30 13:36:41,629 server 17195 4574504448 Exception inside application: No route found for path 'ws/portfolio/'.
Traceback (most recent call last):
  File "/Users/emmidev/.pyenv/versions/3.11.8/lib/python3.11/site-packages/channels/routing.py", line 48, in __call__
    return await application(scope, receive, send)
           ^^^^^^^^^^^^^^^^^^^^^^^^^^^^^^^^^^^^^^^
  File "/Users/emmidev/.pyenv/versions/3.11.8/lib/python3.11/site-packages/channels/sessions.py", line 44, in __call__
    return await self.inner(dict(scope, cookies=cookies), receive, send)
           ^^^^^^^^^^^^^^^^^^^^^^^^^^^^^^^^^^^^^^^^^^^^^^^^^^^^^^^^^^^^^
  File "/Users/emmidev/.pyenv/versions/3.11.8/lib/python3.11/site-packages/channels/sessions.py", line 261, in __call__
    return await self.inner(wrapper.scope, receive, wrapper.send)
           ^^^^^^^^^^^^^^^^^^^^^^^^^^^^^^^^^^^^^^^^^^^^^^^^^^^^^^
  File "/Users/emmidev/.pyenv/versions/3.11.8/lib/python3.11/site-packages/channels/auth.py", line 185, in __call__
    return await super().__call__(scope, receive, send)
           ^^^^^^^^^^^^^^^^^^^^^^^^^^^^^^^^^^^^^^^^^^^^
  File "/Users/emmidev/.pyenv/versions/3.11.8/lib/python3.11/site-packages/channels/middleware.py", line 24, in __call__
    return await self.inner(scope, receive, send)
           ^^^^^^^^^^^^^^^^^^^^^^^^^^^^^^^^^^^^^^
  File "/Users/emmidev/.pyenv/versions/3.11.8/lib/python3.11/site-packages/channels/routing.py", line 136, in __call__
    raise ValueError("No route found for path %r." % path)
ValueError: No route found for path 'ws/portfolio/'.
ERROR 2025-10-30 13:36:46,649 server 17195 4574504448 Exception inside application: No route found for path 'ws/portfolio/'.
Traceback (most recent call last):
  File "/Users/emmidev/.pyenv/versions/3.11.8/lib/python3.11/site-packages/channels/routing.py", line 48, in __call__
    return await application(scope, receive, send)
           ^^^^^^^^^^^^^^^^^^^^^^^^^^^^^^^^^^^^^^^
  File "/Users/emmidev/.pyenv/versions/3.11.8/lib/python3.11/site-packages/channels/sessions.py", line 44, in __call__
    return await self.inner(dict(scope, cookies=cookies), receive, send)
           ^^^^^^^^^^^^^^^^^^^^^^^^^^^^^^^^^^^^^^^^^^^^^^^^^^^^^^^^^^^^^
  File "/Users/emmidev/.pyenv/versions/3.11.8/lib/python3.11/site-packages/channels/sessions.py", line 261, in __call__
    return await self.inner(wrapper.scope, receive, wrapper.send)
           ^^^^^^^^^^^^^^^^^^^^^^^^^^^^^^^^^^^^^^^^^^^^^^^^^^^^^^
  File "/Users/emmidev/.pyenv/versions/3.11.8/lib/python3.11/site-packages/channels/auth.py", line 185, in __call__
    return await super().__call__(scope, receive, send)
           ^^^^^^^^^^^^^^^^^^^^^^^^^^^^^^^^^^^^^^^^^^^^
  File "/Users/emmidev/.pyenv/versions/3.11.8/lib/python3.11/site-packages/channels/middleware.py", line 24, in __call__
    return await self.inner(scope, receive, send)
           ^^^^^^^^^^^^^^^^^^^^^^^^^^^^^^^^^^^^^^
  File "/Users/emmidev/.pyenv/versions/3.11.8/lib/python3.11/site-packages/channels/routing.py", line 136, in __call__
    raise ValueError("No route found for path %r." % path)
ValueError: No route found for path 'ws/portfolio/'.
ERROR 2025-10-30 13:36:50,653 server 17195 4574504448 Exception inside application: No route found for path 'ws/portfolio/'.
Traceback (most recent call last):
  File "/Users/emmidev/.pyenv/versions/3.11.8/lib/python3.11/site-packages/channels/routing.py", line 48, in __call__
    return await application(scope, receive, send)
           ^^^^^^^^^^^^^^^^^^^^^^^^^^^^^^^^^^^^^^^
  File "/Users/emmidev/.pyenv/versions/3.11.8/lib/python3.11/site-packages/channels/sessions.py", line 44, in __call__
    return await self.inner(dict(scope, cookies=cookies), receive, send)
           ^^^^^^^^^^^^^^^^^^^^^^^^^^^^^^^^^^^^^^^^^^^^^^^^^^^^^^^^^^^^^
  File "/Users/emmidev/.pyenv/versions/3.11.8/lib/python3.11/site-packages/channels/sessions.py", line 261, in __call__
    return await self.inner(wrapper.scope, receive, wrapper.send)
           ^^^^^^^^^^^^^^^^^^^^^^^^^^^^^^^^^^^^^^^^^^^^^^^^^^^^^^
  File "/Users/emmidev/.pyenv/versions/3.11.8/lib/python3.11/site-packages/channels/auth.py", line 185, in __call__
    return await super().__call__(scope, receive, send)
           ^^^^^^^^^^^^^^^^^^^^^^^^^^^^^^^^^^^^^^^^^^^^
  File "/Users/emmidev/.pyenv/versions/3.11.8/lib/python3.11/site-packages/channels/middleware.py", line 24, in __call__
    return await self.inner(scope, receive, send)
           ^^^^^^^^^^^^^^^^^^^^^^^^^^^^^^^^^^^^^^
  File "/Users/emmidev/.pyenv/versions/3.11.8/lib/python3.11/site-packages/channels/routing.py", line 136, in __call__
    raise ValueError("No route found for path %r." % path)
ValueError: No route found for path 'ws/portfolio/'.
ERROR 2025-10-30 13:36:53,658 server 17195 4574504448 Exception inside application: No route found for path 'ws/portfolio/'.
Traceback (most recent call last):
  File "/Users/emmidev/.pyenv/versions/3.11.8/lib/python3.11/site-packages/channels/routing.py", line 48, in __call__
    return await application(scope, receive, send)
           ^^^^^^^^^^^^^^^^^^^^^^^^^^^^^^^^^^^^^^^
  File "/Users/emmidev/.pyenv/versions/3.11.8/lib/python3.11/site-packages/channels/sessions.py", line 44, in __call__
    return await self.inner(dict(scope, cookies=cookies), receive, send)
           ^^^^^^^^^^^^^^^^^^^^^^^^^^^^^^^^^^^^^^^^^^^^^^^^^^^^^^^^^^^^^
  File "/Users/emmidev/.pyenv/versions/3.11.8/lib/python3.11/site-packages/channels/sessions.py", line 261, in __call__
    return await self.inner(wrapper.scope, receive, wrapper.send)
           ^^^^^^^^^^^^^^^^^^^^^^^^^^^^^^^^^^^^^^^^^^^^^^^^^^^^^^
  File "/Users/emmidev/.pyenv/versions/3.11.8/lib/python3.11/site-packages/channels/auth.py", line 185, in __call__
    return await super().__call__(scope, receive, send)
           ^^^^^^^^^^^^^^^^^^^^^^^^^^^^^^^^^^^^^^^^^^^^
  File "/Users/emmidev/.pyenv/versions/3.11.8/lib/python3.11/site-packages/channels/middleware.py", line 24, in __call__
    return await self.inner(scope, receive, send)
           ^^^^^^^^^^^^^^^^^^^^^^^^^^^^^^^^^^^^^^
  File "/Users/emmidev/.pyenv/versions/3.11.8/lib/python3.11/site-packages/channels/routing.py", line 136, in __call__
    raise ValueError("No route found for path %r." % path)
ValueError: No route found for path 'ws/portfolio/'.
ERROR 2025-10-30 13:36:58,666 server 17195 4574504448 Exception inside application: No route found for path 'ws/portfolio/'.
Traceback (most recent call last):
  File "/Users/emmidev/.pyenv/versions/3.11.8/lib/python3.11/site-packages/channels/routing.py", line 48, in __call__
    return await application(scope, receive, send)
           ^^^^^^^^^^^^^^^^^^^^^^^^^^^^^^^^^^^^^^^
  File "/Users/emmidev/.pyenv/versions/3.11.8/lib/python3.11/site-packages/channels/sessions.py", line 44, in __call__
    return await self.inner(dict(scope, cookies=cookies), receive, send)
           ^^^^^^^^^^^^^^^^^^^^^^^^^^^^^^^^^^^^^^^^^^^^^^^^^^^^^^^^^^^^^
  File "/Users/emmidev/.pyenv/versions/3.11.8/lib/python3.11/site-packages/channels/sessions.py", line 261, in __call__
    return await self.inner(wrapper.scope, receive, wrapper.send)
           ^^^^^^^^^^^^^^^^^^^^^^^^^^^^^^^^^^^^^^^^^^^^^^^^^^^^^^
  File "/Users/emmidev/.pyenv/versions/3.11.8/lib/python3.11/site-packages/channels/auth.py", line 185, in __call__
    return await super().__call__(scope, receive, send)
           ^^^^^^^^^^^^^^^^^^^^^^^^^^^^^^^^^^^^^^^^^^^^
  File "/Users/emmidev/.pyenv/versions/3.11.8/lib/python3.11/site-packages/channels/middleware.py", line 24, in __call__
    return await self.inner(scope, receive, send)
           ^^^^^^^^^^^^^^^^^^^^^^^^^^^^^^^^^^^^^^
  File "/Users/emmidev/.pyenv/versions/3.11.8/lib/python3.11/site-packages/channels/routing.py", line 136, in __call__
    raise ValueError("No route found for path %r." % path)
ValueError: No route found for path 'ws/portfolio/'.
ERROR 2025-10-30 13:37:01,671 server 17195 4574504448 Exception inside application: No route found for path 'ws/portfolio/'.
Traceback (most recent call last):
  File "/Users/emmidev/.pyenv/versions/3.11.8/lib/python3.11/site-packages/channels/routing.py", line 48, in __call__
    return await application(scope, receive, send)
           ^^^^^^^^^^^^^^^^^^^^^^^^^^^^^^^^^^^^^^^
  File "/Users/emmidev/.pyenv/versions/3.11.8/lib/python3.11/site-packages/channels/sessions.py", line 44, in __call__
    return await self.inner(dict(scope, cookies=cookies), receive, send)
           ^^^^^^^^^^^^^^^^^^^^^^^^^^^^^^^^^^^^^^^^^^^^^^^^^^^^^^^^^^^^^
  File "/Users/emmidev/.pyenv/versions/3.11.8/lib/python3.11/site-packages/channels/sessions.py", line 261, in __call__
    return await self.inner(wrapper.scope, receive, wrapper.send)
           ^^^^^^^^^^^^^^^^^^^^^^^^^^^^^^^^^^^^^^^^^^^^^^^^^^^^^^
  File "/Users/emmidev/.pyenv/versions/3.11.8/lib/python3.11/site-packages/channels/auth.py", line 185, in __call__
    return await super().__call__(scope, receive, send)
           ^^^^^^^^^^^^^^^^^^^^^^^^^^^^^^^^^^^^^^^^^^^^
  File "/Users/emmidev/.pyenv/versions/3.11.8/lib/python3.11/site-packages/channels/middleware.py", line 24, in __call__
    return await self.inner(scope, receive, send)
           ^^^^^^^^^^^^^^^^^^^^^^^^^^^^^^^^^^^^^^
  File "/Users/emmidev/.pyenv/versions/3.11.8/lib/python3.11/site-packages/channels/routing.py", line 136, in __call__
    raise ValueError("No route found for path %r." % path)
ValueError: No route found for path 'ws/portfolio/'.
ERROR 2025-10-30 13:37:06,677 server 17195 4574504448 Exception inside application: No route found for path 'ws/portfolio/'.
Traceback (most recent call last):
  File "/Users/emmidev/.pyenv/versions/3.11.8/lib/python3.11/site-packages/channels/routing.py", line 48, in __call__
    return await application(scope, receive, send)
           ^^^^^^^^^^^^^^^^^^^^^^^^^^^^^^^^^^^^^^^
  File "/Users/emmidev/.pyenv/versions/3.11.8/lib/python3.11/site-packages/channels/sessions.py", line 44, in __call__
    return await self.inner(dict(scope, cookies=cookies), receive, send)
           ^^^^^^^^^^^^^^^^^^^^^^^^^^^^^^^^^^^^^^^^^^^^^^^^^^^^^^^^^^^^^
  File "/Users/emmidev/.pyenv/versions/3.11.8/lib/python3.11/site-packages/channels/sessions.py", line 261, in __call__
    return await self.inner(wrapper.scope, receive, wrapper.send)
           ^^^^^^^^^^^^^^^^^^^^^^^^^^^^^^^^^^^^^^^^^^^^^^^^^^^^^^
  File "/Users/emmidev/.pyenv/versions/3.11.8/lib/python3.11/site-packages/channels/auth.py", line 185, in __call__
    return await super().__call__(scope, receive, send)
           ^^^^^^^^^^^^^^^^^^^^^^^^^^^^^^^^^^^^^^^^^^^^
  File "/Users/emmidev/.pyenv/versions/3.11.8/lib/python3.11/site-packages/channels/middleware.py", line 24, in __call__
    return await self.inner(scope, receive, send)
           ^^^^^^^^^^^^^^^^^^^^^^^^^^^^^^^^^^^^^^
  File "/Users/emmidev/.pyenv/versions/3.11.8/lib/python3.11/site-packages/channels/routing.py", line 136, in __call__
    raise ValueError("No route found for path %r." % path)
ValueError: No route found for path 'ws/portfolio/'.
ERROR 2025-10-30 13:37:10,681 server 17195 4574504448 Exception inside application: No route found for path 'ws/portfolio/'.
Traceback (most recent call last):
  File "/Users/emmidev/.pyenv/versions/3.11.8/lib/python3.11/site-packages/channels/routing.py", line 48, in __call__
    return await application(scope, receive, send)
           ^^^^^^^^^^^^^^^^^^^^^^^^^^^^^^^^^^^^^^^
  File "/Users/emmidev/.pyenv/versions/3.11.8/lib/python3.11/site-packages/channels/sessions.py", line 44, in __call__
    return await self.inner(dict(scope, cookies=cookies), receive, send)
           ^^^^^^^^^^^^^^^^^^^^^^^^^^^^^^^^^^^^^^^^^^^^^^^^^^^^^^^^^^^^^
  File "/Users/emmidev/.pyenv/versions/3.11.8/lib/python3.11/site-packages/channels/sessions.py", line 261, in __call__
    return await self.inner(wrapper.scope, receive, wrapper.send)
           ^^^^^^^^^^^^^^^^^^^^^^^^^^^^^^^^^^^^^^^^^^^^^^^^^^^^^^
  File "/Users/emmidev/.pyenv/versions/3.11.8/lib/python3.11/site-packages/channels/auth.py", line 185, in __call__
    return await super().__call__(scope, receive, send)
           ^^^^^^^^^^^^^^^^^^^^^^^^^^^^^^^^^^^^^^^^^^^^
  File "/Users/emmidev/.pyenv/versions/3.11.8/lib/python3.11/site-packages/channels/middleware.py", line 24, in __call__
    return await self.inner(scope, receive, send)
           ^^^^^^^^^^^^^^^^^^^^^^^^^^^^^^^^^^^^^^
  File "/Users/emmidev/.pyenv/versions/3.11.8/lib/python3.11/site-packages/channels/routing.py", line 136, in __call__
    raise ValueError("No route found for path %r." % path)
ValueError: No route found for path 'ws/portfolio/'.
ERROR 2025-10-30 13:37:14,688 server 17195 4574504448 Exception inside application: No route found for path 'ws/portfolio/'.
Traceback (most recent call last):
  File "/Users/emmidev/.pyenv/versions/3.11.8/lib/python3.11/site-packages/channels/routing.py", line 48, in __call__
    return await application(scope, receive, send)
           ^^^^^^^^^^^^^^^^^^^^^^^^^^^^^^^^^^^^^^^
  File "/Users/emmidev/.pyenv/versions/3.11.8/lib/python3.11/site-packages/channels/sessions.py", line 44, in __call__
    return await self.inner(dict(scope, cookies=cookies), receive, send)
           ^^^^^^^^^^^^^^^^^^^^^^^^^^^^^^^^^^^^^^^^^^^^^^^^^^^^^^^^^^^^^
  File "/Users/emmidev/.pyenv/versions/3.11.8/lib/python3.11/site-packages/channels/sessions.py", line 261, in __call__
    return await self.inner(wrapper.scope, receive, wrapper.send)
           ^^^^^^^^^^^^^^^^^^^^^^^^^^^^^^^^^^^^^^^^^^^^^^^^^^^^^^
  File "/Users/emmidev/.pyenv/versions/3.11.8/lib/python3.11/site-packages/channels/auth.py", line 185, in __call__
    return await super().__call__(scope, receive, send)
           ^^^^^^^^^^^^^^^^^^^^^^^^^^^^^^^^^^^^^^^^^^^^
  File "/Users/emmidev/.pyenv/versions/3.11.8/lib/python3.11/site-packages/channels/middleware.py", line 24, in __call__
    return await self.inner(scope, receive, send)
           ^^^^^^^^^^^^^^^^^^^^^^^^^^^^^^^^^^^^^^
  File "/Users/emmidev/.pyenv/versions/3.11.8/lib/python3.11/site-packages/channels/routing.py", line 136, in __call__
    raise ValueError("No route found for path %r." % path)
ValueError: No route found for path 'ws/portfolio/'.
ERROR 2025-10-30 13:37:18,693 server 17195 4574504448 Exception inside application: No route found for path 'ws/portfolio/'.
Traceback (most recent call last):
  File "/Users/emmidev/.pyenv/versions/3.11.8/lib/python3.11/site-packages/channels/routing.py", line 48, in __call__
    return await application(scope, receive, send)
           ^^^^^^^^^^^^^^^^^^^^^^^^^^^^^^^^^^^^^^^
  File "/Users/emmidev/.pyenv/versions/3.11.8/lib/python3.11/site-packages/channels/sessions.py", line 44, in __call__
    return await self.inner(dict(scope, cookies=cookies), receive, send)
           ^^^^^^^^^^^^^^^^^^^^^^^^^^^^^^^^^^^^^^^^^^^^^^^^^^^^^^^^^^^^^
  File "/Users/emmidev/.pyenv/versions/3.11.8/lib/python3.11/site-packages/channels/sessions.py", line 261, in __call__
    return await self.inner(wrapper.scope, receive, wrapper.send)
           ^^^^^^^^^^^^^^^^^^^^^^^^^^^^^^^^^^^^^^^^^^^^^^^^^^^^^^
  File "/Users/emmidev/.pyenv/versions/3.11.8/lib/python3.11/site-packages/channels/auth.py", line 185, in __call__
    return await super().__call__(scope, receive, send)
           ^^^^^^^^^^^^^^^^^^^^^^^^^^^^^^^^^^^^^^^^^^^^
  File "/Users/emmidev/.pyenv/versions/3.11.8/lib/python3.11/site-packages/channels/middleware.py", line 24, in __call__
    return await self.inner(scope, receive, send)
           ^^^^^^^^^^^^^^^^^^^^^^^^^^^^^^^^^^^^^^
  File "/Users/emmidev/.pyenv/versions/3.11.8/lib/python3.11/site-packages/channels/routing.py", line 136, in __call__
    raise ValueError("No route found for path %r." % path)
ValueError: No route found for path 'ws/portfolio/'.
ERROR 2025-10-30 13:37:22,700 server 17195 4574504448 Exception inside application: No route found for path 'ws/portfolio/'.
Traceback (most recent call last):
  File "/Users/emmidev/.pyenv/versions/3.11.8/lib/python3.11/site-packages/channels/routing.py", line 48, in __call__
    return await application(scope, receive, send)
           ^^^^^^^^^^^^^^^^^^^^^^^^^^^^^^^^^^^^^^^
  File "/Users/emmidev/.pyenv/versions/3.11.8/lib/python3.11/site-packages/channels/sessions.py", line 44, in __call__
    return await self.inner(dict(scope, cookies=cookies), receive, send)
           ^^^^^^^^^^^^^^^^^^^^^^^^^^^^^^^^^^^^^^^^^^^^^^^^^^^^^^^^^^^^^
  File "/Users/emmidev/.pyenv/versions/3.11.8/lib/python3.11/site-packages/channels/sessions.py", line 261, in __call__
    return await self.inner(wrapper.scope, receive, wrapper.send)
           ^^^^^^^^^^^^^^^^^^^^^^^^^^^^^^^^^^^^^^^^^^^^^^^^^^^^^^
  File "/Users/emmidev/.pyenv/versions/3.11.8/lib/python3.11/site-packages/channels/auth.py", line 185, in __call__
    return await super().__call__(scope, receive, send)
           ^^^^^^^^^^^^^^^^^^^^^^^^^^^^^^^^^^^^^^^^^^^^
  File "/Users/emmidev/.pyenv/versions/3.11.8/lib/python3.11/site-packages/channels/middleware.py", line 24, in __call__
    return await self.inner(scope, receive, send)
           ^^^^^^^^^^^^^^^^^^^^^^^^^^^^^^^^^^^^^^
  File "/Users/emmidev/.pyenv/versions/3.11.8/lib/python3.11/site-packages/channels/routing.py", line 136, in __call__
    raise ValueError("No route found for path %r." % path)
ValueError: No route found for path 'ws/portfolio/'.
ERROR 2025-10-30 13:37:26,707 server 17195 4574504448 Exception inside application: No route found for path 'ws/portfolio/'.
Traceback (most recent call last):
  File "/Users/emmidev/.pyenv/versions/3.11.8/lib/python3.11/site-packages/channels/routing.py", line 48, in __call__
    return await application(scope, receive, send)
           ^^^^^^^^^^^^^^^^^^^^^^^^^^^^^^^^^^^^^^^
  File "/Users/emmidev/.pyenv/versions/3.11.8/lib/python3.11/site-packages/channels/sessions.py", line 44, in __call__
    return await self.inner(dict(scope, cookies=cookies), receive, send)
           ^^^^^^^^^^^^^^^^^^^^^^^^^^^^^^^^^^^^^^^^^^^^^^^^^^^^^^^^^^^^^
  File "/Users/emmidev/.pyenv/versions/3.11.8/lib/python3.11/site-packages/channels/sessions.py", line 261, in __call__
    return await self.inner(wrapper.scope, receive, wrapper.send)
           ^^^^^^^^^^^^^^^^^^^^^^^^^^^^^^^^^^^^^^^^^^^^^^^^^^^^^^
  File "/Users/emmidev/.pyenv/versions/3.11.8/lib/python3.11/site-packages/channels/auth.py", line 185, in __call__
    return await super().__call__(scope, receive, send)
           ^^^^^^^^^^^^^^^^^^^^^^^^^^^^^^^^^^^^^^^^^^^^
  File "/Users/emmidev/.pyenv/versions/3.11.8/lib/python3.11/site-packages/channels/middleware.py", line 24, in __call__
    return await self.inner(scope, receive, send)
           ^^^^^^^^^^^^^^^^^^^^^^^^^^^^^^^^^^^^^^
  File "/Users/emmidev/.pyenv/versions/3.11.8/lib/python3.11/site-packages/channels/routing.py", line 136, in __call__
    raise ValueError("No route found for path %r." % path)
ValueError: No route found for path 'ws/portfolio/'.
ERROR 2025-10-30 13:37:32,716 server 17195 4574504448 Exception inside application: No route found for path 'ws/portfolio/'.
Traceback (most recent call last):
  File "/Users/emmidev/.pyenv/versions/3.11.8/lib/python3.11/site-packages/channels/routing.py", line 48, in __call__
    return await application(scope, receive, send)
           ^^^^^^^^^^^^^^^^^^^^^^^^^^^^^^^^^^^^^^^
  File "/Users/emmidev/.pyenv/versions/3.11.8/lib/python3.11/site-packages/channels/sessions.py", line 44, in __call__
    return await self.inner(dict(scope, cookies=cookies), receive, send)
           ^^^^^^^^^^^^^^^^^^^^^^^^^^^^^^^^^^^^^^^^^^^^^^^^^^^^^^^^^^^^^
  File "/Users/emmidev/.pyenv/versions/3.11.8/lib/python3.11/site-packages/channels/sessions.py", line 261, in __call__
    return await self.inner(wrapper.scope, receive, wrapper.send)
           ^^^^^^^^^^^^^^^^^^^^^^^^^^^^^^^^^^^^^^^^^^^^^^^^^^^^^^
  File "/Users/emmidev/.pyenv/versions/3.11.8/lib/python3.11/site-packages/channels/auth.py", line 185, in __call__
    return await super().__call__(scope, receive, send)
           ^^^^^^^^^^^^^^^^^^^^^^^^^^^^^^^^^^^^^^^^^^^^
  File "/Users/emmidev/.pyenv/versions/3.11.8/lib/python3.11/site-packages/channels/middleware.py", line 24, in __call__
    return await self.inner(scope, receive, send)
           ^^^^^^^^^^^^^^^^^^^^^^^^^^^^^^^^^^^^^^
  File "/Users/emmidev/.pyenv/versions/3.11.8/lib/python3.11/site-packages/channels/routing.py", line 136, in __call__
    raise ValueError("No route found for path %r." % path)
ValueError: No route found for path 'ws/portfolio/'.
ERROR 2025-10-30 13:37:35,721 server 17195 4574504448 Exception inside application: No route found for path 'ws/portfolio/'.
Traceback (most recent call last):
  File "/Users/emmidev/.pyenv/versions/3.11.8/lib/python3.11/site-packages/channels/routing.py", line 48, in __call__
    return await application(scope, receive, send)
           ^^^^^^^^^^^^^^^^^^^^^^^^^^^^^^^^^^^^^^^
  File "/Users/emmidev/.pyenv/versions/3.11.8/lib/python3.11/site-packages/channels/sessions.py", line 44, in __call__
    return await self.inner(dict(scope, cookies=cookies), receive, send)
           ^^^^^^^^^^^^^^^^^^^^^^^^^^^^^^^^^^^^^^^^^^^^^^^^^^^^^^^^^^^^^
  File "/Users/emmidev/.pyenv/versions/3.11.8/lib/python3.11/site-packages/channels/sessions.py", line 261, in __call__
    return await self.inner(wrapper.scope, receive, wrapper.send)
           ^^^^^^^^^^^^^^^^^^^^^^^^^^^^^^^^^^^^^^^^^^^^^^^^^^^^^^
  File "/Users/emmidev/.pyenv/versions/3.11.8/lib/python3.11/site-packages/channels/auth.py", line 185, in __call__
    return await super().__call__(scope, receive, send)
           ^^^^^^^^^^^^^^^^^^^^^^^^^^^^^^^^^^^^^^^^^^^^
  File "/Users/emmidev/.pyenv/versions/3.11.8/lib/python3.11/site-packages/channels/middleware.py", line 24, in __call__
    return await self.inner(scope, receive, send)
           ^^^^^^^^^^^^^^^^^^^^^^^^^^^^^^^^^^^^^^
  File "/Users/emmidev/.pyenv/versions/3.11.8/lib/python3.11/site-packages/channels/routing.py", line 136, in __call__
    raise ValueError("No route found for path %r." % path)
ValueError: No route found for path 'ws/portfolio/'.
ERROR 2025-10-30 13:37:42,732 server 17195 4574504448 Exception inside application: No route found for path 'ws/portfolio/'.
Traceback (most recent call last):
  File "/Users/emmidev/.pyenv/versions/3.11.8/lib/python3.11/site-packages/channels/routing.py", line 48, in __call__
    return await application(scope, receive, send)
           ^^^^^^^^^^^^^^^^^^^^^^^^^^^^^^^^^^^^^^^
  File "/Users/emmidev/.pyenv/versions/3.11.8/lib/python3.11/site-packages/channels/sessions.py", line 44, in __call__
    return await self.inner(dict(scope, cookies=cookies), receive, send)
           ^^^^^^^^^^^^^^^^^^^^^^^^^^^^^^^^^^^^^^^^^^^^^^^^^^^^^^^^^^^^^
  File "/Users/emmidev/.pyenv/versions/3.11.8/lib/python3.11/site-packages/channels/sessions.py", line 261, in __call__
    return await self.inner(wrapper.scope, receive, wrapper.send)
           ^^^^^^^^^^^^^^^^^^^^^^^^^^^^^^^^^^^^^^^^^^^^^^^^^^^^^^
  File "/Users/emmidev/.pyenv/versions/3.11.8/lib/python3.11/site-packages/channels/auth.py", line 185, in __call__
    return await super().__call__(scope, receive, send)
           ^^^^^^^^^^^^^^^^^^^^^^^^^^^^^^^^^^^^^^^^^^^^
  File "/Users/emmidev/.pyenv/versions/3.11.8/lib/python3.11/site-packages/channels/middleware.py", line 24, in __call__
    return await self.inner(scope, receive, send)
           ^^^^^^^^^^^^^^^^^^^^^^^^^^^^^^^^^^^^^^
  File "/Users/emmidev/.pyenv/versions/3.11.8/lib/python3.11/site-packages/channels/routing.py", line 136, in __call__
    raise ValueError("No route found for path %r." % path)
ValueError: No route found for path 'ws/portfolio/'.
ERROR 2025-10-30 13:37:43,740 server 17195 4574504448 Exception inside application: No route found for path 'ws/portfolio/'.
Traceback (most recent call last):
  File "/Users/emmidev/.pyenv/versions/3.11.8/lib/python3.11/site-packages/channels/routing.py", line 48, in __call__
    return await application(scope, receive, send)
           ^^^^^^^^^^^^^^^^^^^^^^^^^^^^^^^^^^^^^^^
  File "/Users/emmidev/.pyenv/versions/3.11.8/lib/python3.11/site-packages/channels/sessions.py", line 44, in __call__
    return await self.inner(dict(scope, cookies=cookies), receive, send)
           ^^^^^^^^^^^^^^^^^^^^^^^^^^^^^^^^^^^^^^^^^^^^^^^^^^^^^^^^^^^^^
  File "/Users/emmidev/.pyenv/versions/3.11.8/lib/python3.11/site-packages/channels/sessions.py", line 261, in __call__
    return await self.inner(wrapper.scope, receive, wrapper.send)
           ^^^^^^^^^^^^^^^^^^^^^^^^^^^^^^^^^^^^^^^^^^^^^^^^^^^^^^
  File "/Users/emmidev/.pyenv/versions/3.11.8/lib/python3.11/site-packages/channels/auth.py", line 185, in __call__
    return await super().__call__(scope, receive, send)
           ^^^^^^^^^^^^^^^^^^^^^^^^^^^^^^^^^^^^^^^^^^^^
  File "/Users/emmidev/.pyenv/versions/3.11.8/lib/python3.11/site-packages/channels/middleware.py", line 24, in __call__
    return await self.inner(scope, receive, send)
           ^^^^^^^^^^^^^^^^^^^^^^^^^^^^^^^^^^^^^^
  File "/Users/emmidev/.pyenv/versions/3.11.8/lib/python3.11/site-packages/channels/routing.py", line 136, in __call__
    raise ValueError("No route found for path %r." % path)
ValueError: No route found for path 'ws/portfolio/'.
ERROR 2025-10-30 13:37:51,747 server 17195 4574504448 Exception inside application: No route found for path 'ws/portfolio/'.
Traceback (most recent call last):
  File "/Users/emmidev/.pyenv/versions/3.11.8/lib/python3.11/site-packages/channels/routing.py", line 48, in __call__
    return await application(scope, receive, send)
           ^^^^^^^^^^^^^^^^^^^^^^^^^^^^^^^^^^^^^^^
  File "/Users/emmidev/.pyenv/versions/3.11.8/lib/python3.11/site-packages/channels/sessions.py", line 44, in __call__
    return await self.inner(dict(scope, cookies=cookies), receive, send)
           ^^^^^^^^^^^^^^^^^^^^^^^^^^^^^^^^^^^^^^^^^^^^^^^^^^^^^^^^^^^^^
  File "/Users/emmidev/.pyenv/versions/3.11.8/lib/python3.11/site-packages/channels/sessions.py", line 261, in __call__
    return await self.inner(wrapper.scope, receive, wrapper.send)
           ^^^^^^^^^^^^^^^^^^^^^^^^^^^^^^^^^^^^^^^^^^^^^^^^^^^^^^
  File "/Users/emmidev/.pyenv/versions/3.11.8/lib/python3.11/site-packages/channels/auth.py", line 185, in __call__
    return await super().__call__(scope, receive, send)
           ^^^^^^^^^^^^^^^^^^^^^^^^^^^^^^^^^^^^^^^^^^^^
  File "/Users/emmidev/.pyenv/versions/3.11.8/lib/python3.11/site-packages/channels/middleware.py", line 24, in __call__
    return await self.inner(scope, receive, send)
           ^^^^^^^^^^^^^^^^^^^^^^^^^^^^^^^^^^^^^^
  File "/Users/emmidev/.pyenv/versions/3.11.8/lib/python3.11/site-packages/channels/routing.py", line 136, in __call__
    raise ValueError("No route found for path %r." % path)
ValueError: No route found for path 'ws/portfolio/'.
INFO 2025-10-30 13:38:30,170 autoreload 17807 4462118400 Watching for file changes with StatReloader
WARNING 2025-10-30 13:38:32,193 log 17807 123145481445376 Not Found: /ws/market/
WARNING 2025-10-30 13:38:32,194 log 17807 123145498234880 Not Found: /ws/market/
INFO 2025-10-30 13:38:34,135 crypto_api_service 17807 123145481445376 CoinGecko API success: fetched 5 coins
INFO 2025-10-30 13:38:34,141 crypto_api_service 17807 123145481445376 Successfully fetched data from _fetch_from_coingecko
INFO 2025-10-30 13:38:34,186 crypto_api_service 17807 123145481445376 Updated 5 cryptocurrencies
WARNING 2025-10-30 13:38:36,105 log 17807 123145516097536 Not Found: /ws/market/
WARNING 2025-10-30 13:38:36,165 log 17807 123145516097536 Not Found: /ws/market/
WARNING 2025-10-30 13:38:40,112 log 17807 123145515560960 Not Found: /ws/market/
WARNING 2025-10-30 13:38:40,340 log 17807 123145515560960 Not Found: /ws/market/
INFO 2025-10-30 13:38:52,205 cli 17922 4575172096 Starting server at tcp:port=8000:interface=127.0.0.1
INFO 2025-10-30 13:38:52,206 server 17922 4575172096 HTTP/2 support enabled
INFO 2025-10-30 13:38:52,206 server 17922 4575172096 Configuring endpoint tcp:port=8000:interface=127.0.0.1
INFO 2025-10-30 13:38:52,207 server 17922 4575172096 Listening on TCP address 127.0.0.1:8000
INFO 2025-10-30 13:38:53,829 consumers 17922 4575172096 Market WebSocket connected: specific..inmemory!jAksjoYOCxbQ
INFO 2025-10-30 13:38:54,775 crypto_api_service 17922 123145322782720 CoinGecko: Fetched 283 data points for BTC
INFO 2025-10-30 13:38:56,107 consumers 17922 4575172096 Market WebSocket connected: specific..inmemory!VEiGerAsUmGj
INFO 2025-10-30 13:38:56,726 crypto_api_service 17922 123145340645376 CoinGecko API success: fetched 5 coins
INFO 2025-10-30 13:38:56,733 crypto_api_service 17922 123145340645376 Successfully fetched data from _fetch_from_coingecko
INFO 2025-10-30 13:38:56,798 crypto_api_service 17922 123145340645376 Updated 5 cryptocurrencies
INFO 2025-10-30 13:38:56,805 crypto_api_service 17922 123145322782720 CoinGecko: Fetched 283 data points for BTC
INFO 2025-10-30 13:39:09,953 consumers 17922 4575172096 Market WebSocket connected: specific..inmemory!bvrYzxQbSTuq
INFO 2025-10-30 13:39:10,691 crypto_api_service 17922 123145322782720 CoinGecko: Fetched 283 data points for BTC
INFO 2025-10-30 13:39:24,360 consumers 17922 4575172096 Market WebSocket disconnected: specific..inmemory!VEiGerAsUmGj
INFO 2025-10-30 13:39:25,093 consumers 17922 4575172096 Market WebSocket connected: specific..inmemory!ZArlKqgWAUrc
INFO 2025-10-30 13:39:28,997 crypto_api_service 17922 123145322782720 CoinGecko: Fetched 283 data points for BTC
INFO 2025-10-30 13:39:29,117 crypto_api_service 17922 123145340108800 CoinGecko API success: fetched 5 coins
INFO 2025-10-30 13:39:29,120 crypto_api_service 17922 123145340108800 Successfully fetched data from _fetch_from_coingecko
INFO 2025-10-30 13:39:29,140 crypto_api_service 17922 123145340108800 Updated 5 cryptocurrencies
INFO 2025-10-30 13:39:29,314 consumers 17922 4575172096 Market WebSocket disconnected: specific..inmemory!bvrYzxQbSTuq
INFO 2025-10-30 13:39:55,237 api_views 17922 123145340108800 Buy API called with data: {'transaction_type': 'BUY', 'cryptocurrency': 'ETH', 'quantity': 0.05, 'price_per_unit': 3792.7, 'total_amount': 189.824635, 'currency': 'USD'}
INFO 2025-10-30 13:39:55,248 api_views 17922 123145340108800 Balance updated for aghason.emmanuel@gmail.com: -189.82 USD, +0.05000000 ETH
INFO 2025-10-30 13:39:55,257 email_service 17922 123145340108800 Attempting to send verification email to aghason.emmanuel@gmail.com
INFO 2025-10-30 13:39:55,257 email_service 17922 123145340108800 Using SMTP: localhost:25
INFO 2025-10-30 13:39:55,258 email_service 17922 123145340108800 From: aghason.emmanuel@gmail.com
INFO 2025-10-30 13:39:55,424 email_service 17922 123145340108800 Verification code email sent successfully to aghason.emmanuel@gmail.com
INFO 2025-10-30 13:39:55,424 api_views 17922 123145340108800 Verification code sent to aghason.emmanuel@gmail.com
INFO 2025-10-30 13:40:23,926 consumers 17922 4575172096 Market WebSocket disconnected: specific..inmemory!ZArlKqgWAUrc
INFO 2025-10-30 13:40:24,609 consumers 17922 4575172096 Market WebSocket connected: specific..inmemory!EDTizgjiCudn
INFO 2025-10-30 13:40:26,932 crypto_api_service 17922 123145322782720 CoinGecko: Fetched 283 data points for BTC
INFO 2025-10-30 13:40:36,253 crypto_api_service 17922 123145340108800 CoinGecko API success: fetched 5 coins
INFO 2025-10-30 13:40:36,256 crypto_api_service 17922 123145340108800 Successfully fetched data from _fetch_from_coingecko
INFO 2025-10-30 13:40:36,271 crypto_api_service 17922 123145340108800 Updated 5 cryptocurrencies
INFO 2025-10-30 13:41:33,983 consumers 17922 4575172096 Market WebSocket disconnected: specific..inmemory!EDTizgjiCudn
INFO 2025-10-30 13:41:34,172 consumers 17922 4575172096 Market WebSocket connected: specific..inmemory!LDUKzcOVqhnM
INFO 2025-10-30 13:41:36,662 crypto_api_service 17922 123145322782720 CoinGecko: Fetched 283 data points for BTC
INFO 2025-10-30 13:41:48,930 api_views 17922 123145340108800 Buy API called with data: {'transaction_type': 'BUY', 'cryptocurrency': 'ETH', 'quantity': 1, 'price_per_unit': 3786.95, 'total_amount': 3790.73695, 'currency': 'USD'}
INFO 2025-10-30 13:41:48,941 api_views 17922 123145340108800 Balance updated for aghason.emmanuel@gmail.com: -3790.74 USD, +1.00000000 ETH
INFO 2025-10-30 13:41:48,952 email_service 17922 123145340108800 Attempting to send verification email to aghason.emmanuel@gmail.com
INFO 2025-10-30 13:41:48,953 email_service 17922 123145340108800 Using SMTP: localhost:25
INFO 2025-10-30 13:41:48,953 email_service 17922 123145340108800 From: aghason.emmanuel@gmail.com
INFO 2025-10-30 13:41:48,957 email_service 17922 123145340108800 Verification code email sent successfully to aghason.emmanuel@gmail.com
INFO 2025-10-30 13:41:48,957 api_views 17922 123145340108800 Verification code sent to aghason.emmanuel@gmail.com
INFO 2025-10-30 13:42:39,610 consumers 17922 4575172096 Market WebSocket disconnected: specific..inmemory!LDUKzcOVqhnM
INFO 2025-10-30 13:42:39,805 consumers 17922 4575172096 Market WebSocket connected: specific..inmemory!IRGjrpSbVTjp
INFO 2025-10-30 13:42:41,194 crypto_api_service 17922 123145322782720 CoinGecko: Fetched 283 data points for BTC
INFO 2025-10-30 13:42:59,181 crypto_api_service 17922 123145340108800 CoinGecko API success: fetched 5 coins
INFO 2025-10-30 13:42:59,183 crypto_api_service 17922 123145340108800 Successfully fetched data from _fetch_from_coingecko
INFO 2025-10-30 13:42:59,202 crypto_api_service 17922 123145340108800 Updated 5 cryptocurrencies
INFO 2025-10-30 13:43:33,922 api_views 17922 123145340108800 Buy API called with data: {'transaction_type': 'BUY', 'cryptocurrency': 'LTC', 'quantity': 10, 'price_per_unit': 94.11, 'total_amount': 942.0411, 'currency': 'USD'}
INFO 2025-10-30 13:43:33,935 api_views 17922 123145340108800 Balance updated for aghason.emmanuel@gmail.com: -942.04 USD, +10.00000000 LTC
INFO 2025-10-30 13:43:33,947 email_service 17922 123145340108800 Attempting to send verification email to aghason.emmanuel@gmail.com
INFO 2025-10-30 13:43:33,948 email_service 17922 123145340108800 Using SMTP: localhost:25
INFO 2025-10-30 13:43:33,948 email_service 17922 123145340108800 From: aghason.emmanuel@gmail.com
INFO 2025-10-30 13:43:33,952 email_service 17922 123145340108800 Verification code email sent successfully to aghason.emmanuel@gmail.com
INFO 2025-10-30 13:43:33,952 api_views 17922 123145340108800 Verification code sent to aghason.emmanuel@gmail.com
INFO 2025-10-30 13:43:57,091 consumers 17922 4575172096 Market WebSocket disconnected: specific..inmemory!IRGjrpSbVTjp
INFO 2025-10-30 13:43:57,262 consumers 17922 4575172096 Market WebSocket connected: specific..inmemory!jMpnuQokopFJ
INFO 2025-10-30 13:43:58,548 crypto_api_service 17922 123145322782720 CoinGecko: Fetched 283 data points for BTC
INFO 2025-10-30 13:44:13,291 crypto_api_service 17922 123145340108800 CoinGecko API success: fetched 5 coins
INFO 2025-10-30 13:44:13,295 crypto_api_service 17922 123145340108800 Successfully fetched data from _fetch_from_coingecko
INFO 2025-10-30 13:44:13,308 crypto_api_service 17922 123145340108800 Updated 5 cryptocurrencies
INFO 2025-10-30 13:46:08,620 api_views 17922 123145340108800 Buy API called with data: {'transaction_type': 'BUY', 'cryptocurrency': 'LTC', 'quantity': 50, 'price_per_unit': 93.97, 'total_amount': 4703.1985, 'currency': 'USD'}
INFO 2025-10-30 13:46:08,631 api_views 17922 123145340108800 Balance updated for aghason.emmanuel@gmail.com: -4703.20 USD, +50.00000000 LTC
INFO 2025-10-30 13:46:08,645 email_service 17922 123145340108800 Attempting to send verification email to aghason.emmanuel@gmail.com
INFO 2025-10-30 13:46:08,645 email_service 17922 123145340108800 Using SMTP: localhost:25
INFO 2025-10-30 13:46:08,645 email_service 17922 123145340108800 From: aghason.emmanuel@gmail.com
INFO 2025-10-30 13:46:08,647 email_service 17922 123145340108800 Verification code email sent successfully to aghason.emmanuel@gmail.com
INFO 2025-10-30 13:46:08,647 api_views 17922 123145340108800 Verification code sent to aghason.emmanuel@gmail.com
INFO 2025-10-30 13:46:32,726 consumers 17922 4575172096 Market WebSocket disconnected: specific..inmemory!jMpnuQokopFJ
INFO 2025-10-30 13:46:33,312 consumers 17922 4575172096 Market WebSocket connected: specific..inmemory!ezChDPYrEcRM
INFO 2025-10-30 13:46:34,805 crypto_api_service 17922 123145322782720 CoinGecko: Fetched 283 data points for BTC
INFO 2025-10-30 13:46:39,031 crypto_api_service 17922 123145340108800 CoinGecko API success: fetched 5 coins
INFO 2025-10-30 13:46:39,036 crypto_api_service 17922 123145340108800 Successfully fetched data from _fetch_from_coingecko
INFO 2025-10-30 13:46:39,051 crypto_api_service 17922 123145340108800 Updated 5 cryptocurrencies
INFO 2025-10-30 13:47:45,606 api_views 17922 123145340108800 Buy API called with data: {'transaction_type': 'BUY', 'cryptocurrency': 'TRX', 'quantity': 500, 'price_per_unit': 0.290893, 'total_amount': 145.5919465, 'currency': 'USD'}
INFO 2025-10-30 13:47:45,624 api_views 17922 123145340108800 Balance updated for aghason.emmanuel@gmail.com: -145.59 USD, +500.00000000 TRX
INFO 2025-10-30 13:47:45,636 email_service 17922 123145340108800 Attempting to send verification email to aghason.emmanuel@gmail.com
INFO 2025-10-30 13:47:45,636 email_service 17922 123145340108800 Using SMTP: localhost:25
INFO 2025-10-30 13:47:45,636 email_service 17922 123145340108800 From: aghason.emmanuel@gmail.com
INFO 2025-10-30 13:47:45,639 email_service 17922 123145340108800 Verification code email sent successfully to aghason.emmanuel@gmail.com
INFO 2025-10-30 13:47:45,639 api_views 17922 123145340108800 Verification code sent to aghason.emmanuel@gmail.com
INFO 2025-10-30 13:48:07,602 consumers 17922 4575172096 Market WebSocket disconnected: specific..inmemory!ezChDPYrEcRM
INFO 2025-10-30 13:48:07,824 consumers 17922 4575172096 Market WebSocket connected: specific..inmemory!hxxYyTqbGkoB
INFO 2025-10-30 13:48:08,734 crypto_api_service 17922 123145322782720 CoinGecko: Fetched 283 data points for BTC
INFO 2025-10-30 13:48:13,599 crypto_api_service 17922 123145340108800 CoinGecko API success: fetched 5 coins
INFO 2025-10-30 13:48:13,602 crypto_api_service 17922 123145340108800 Successfully fetched data from _fetch_from_coingecko
INFO 2025-10-30 13:48:13,621 crypto_api_service 17922 123145340108800 Updated 5 cryptocurrencies
INFO 2025-10-30 13:51:15,464 crypto_api_service 17922 123145340108800 CoinGecko API success: fetched 5 coins
INFO 2025-10-30 13:51:15,473 crypto_api_service 17922 123145340108800 Successfully fetched data from _fetch_from_coingecko
INFO 2025-10-30 13:51:15,529 crypto_api_service 17922 123145340108800 Updated 5 cryptocurrencies
INFO 2025-10-30 13:51:16,100 crypto_api_service 17922 123145356898304 CoinGecko API success: fetched 5 coins
INFO 2025-10-30 13:51:16,105 crypto_api_service 17922 123145356898304 Successfully fetched data from _fetch_from_coingecko
INFO 2025-10-30 13:51:16,136 crypto_api_service 17922 123145356898304 Updated 5 cryptocurrencies
INFO 2025-10-30 13:52:28,295 crypto_api_service 17922 123145340108800 CoinGecko API success: fetched 5 coins
INFO 2025-10-30 13:52:28,297 crypto_api_service 17922 123145340108800 Successfully fetched data from _fetch_from_coingecko
INFO 2025-10-30 13:52:28,317 crypto_api_service 17922 123145340108800 Updated 5 cryptocurrencies
INFO 2025-10-30 13:52:33,383 consumers 17922 4575172096 Market WebSocket connected: specific..inmemory!pWuxhjighbVe
INFO 2025-10-30 13:52:34,127 crypto_api_service 17922 123145322782720 CoinGecko: Fetched 282 data points for BTC
INFO 2025-10-30 14:10:03,538 server 17922 4575172096 Killed 3 pending application instances
